Sending magic packet to 255.255.255.255:9 with BC:5F:F4:5C:85:B9
Sending magic packet to 255.255.255.255:9 with BC:5F:F4:5C:85:B9
Sending magic packet to 255.255.255.255:9 with BC:5F:F4:5C:85:B9
Sending magic packet to 255.255.255.255:9 with BC:5F:F4:5C:85:B9
Ignoring exception in on_message
Traceback (most recent call last):
  File "/home/pi/.local/lib/python3.7/site-packages/discord/client.py", line 312, in _run_event
    await coro(*args, **kwargs)
  File "dischat_2.py", line 122, in on_message
    await message.delete()
  File "/home/pi/.local/lib/python3.7/site-packages/discord/message.py", line 760, in delete
    await self._state.http.delete_message(self.channel.id, self.id)
  File "/home/pi/.local/lib/python3.7/site-packages/discord/http.py", line 243, in request
    raise NotFound(r, data)
discord.errors.NotFound: 404 Not Found (error code: 10008): Unknown Message
Ignoring exception in on_message
Traceback (most recent call last):
  File "/home/pi/.local/lib/python3.7/site-packages/discord/client.py", line 312, in _run_event
    await coro(*args, **kwargs)
  File "dischat_2.py", line 122, in on_message
    await message.delete()
  File "/home/pi/.local/lib/python3.7/site-packages/discord/message.py", line 760, in delete
    await self._state.http.delete_message(self.channel.id, self.id)
  File "/home/pi/.local/lib/python3.7/site-packages/discord/http.py", line 243, in request
    raise NotFound(r, data)
discord.errors.NotFound: 404 Not Found (error code: 10008): Unknown Message
Sending magic packet to 255.255.255.255:9 with BC:5F:F4:5C:85:B9
Sending magic packet to 255.255.255.255:9 with BC:5F:F4:5C:85:B9
Ignoring exception in on_message
Traceback (most recent call last):
  File "/home/pi/.local/lib/python3.7/site-packages/discord/client.py", line 312, in _run_event
    await coro(*args, **kwargs)
  File "dischat_2.py", line 141, in on_message
    await message.delete()
  File "/home/pi/.local/lib/python3.7/site-packages/discord/message.py", line 760, in delete
    await self._state.http.delete_message(self.channel.id, self.id)
  File "/home/pi/.local/lib/python3.7/site-packages/discord/http.py", line 243, in request
    raise NotFound(r, data)
discord.errors.NotFound: 404 Not Found (error code: 10008): Unknown Message
Ignoring exception in on_message
Traceback (most recent call last):
  File "/home/pi/.local/lib/python3.7/site-packages/discord/client.py", line 312, in _run_event
    await coro(*args, **kwargs)
  File "dischat_2.py", line 141, in on_message
    await message.delete()
  File "/home/pi/.local/lib/python3.7/site-packages/discord/message.py", line 760, in delete
    await self._state.http.delete_message(self.channel.id, self.id)
  File "/home/pi/.local/lib/python3.7/site-packages/discord/http.py", line 243, in request
    raise NotFound(r, data)
discord.errors.NotFound: 404 Not Found (error code: 10008): Unknown Message
Ignoring exception in on_message
Traceback (most recent call last):
  File "/home/pi/.local/lib/python3.7/site-packages/discord/client.py", line 312, in _run_event
    await coro(*args, **kwargs)
  File "dischat_2.py", line 141, in on_message
    await message.delete()
  File "/home/pi/.local/lib/python3.7/site-packages/discord/message.py", line 760, in delete
    await self._state.http.delete_message(self.channel.id, self.id)
  File "/home/pi/.local/lib/python3.7/site-packages/discord/http.py", line 243, in request
    raise NotFound(r, data)
discord.errors.NotFound: 404 Not Found (error code: 10008): Unknown Message
Ignoring exception in on_message
Traceback (most recent call last):
  File "/home/pi/.local/lib/python3.7/site-packages/discord/client.py", line 312, in _run_event
    await coro(*args, **kwargs)
  File "dischat_2.py", line 141, in on_message
    await message.delete()
  File "/home/pi/.local/lib/python3.7/site-packages/discord/message.py", line 760, in delete
    await self._state.http.delete_message(self.channel.id, self.id)
  File "/home/pi/.local/lib/python3.7/site-packages/discord/http.py", line 243, in request
    raise NotFound(r, data)
discord.errors.NotFound: 404 Not Found (error code: 10008): Unknown Message
Ignoring exception in on_message
Traceback (most recent call last):
  File "/home/pi/.local/lib/python3.7/site-packages/discord/client.py", line 312, in _run_event
    await coro(*args, **kwargs)
  File "dischat_2.py", line 141, in on_message
    await message.delete()
  File "/home/pi/.local/lib/python3.7/site-packages/discord/message.py", line 760, in delete
    await self._state.http.delete_message(self.channel.id, self.id)
  File "/home/pi/.local/lib/python3.7/site-packages/discord/http.py", line 243, in request
    raise NotFound(r, data)
discord.errors.NotFound: 404 Not Found (error code: 10008): Unknown Message
Ignoring exception in on_message
Traceback (most recent call last):
  File "/home/pi/.local/lib/python3.7/site-packages/discord/client.py", line 312, in _run_event
    await coro(*args, **kwargs)
  File "dischat_2.py", line 141, in on_message
    await message.delete()
  File "/home/pi/.local/lib/python3.7/site-packages/discord/message.py", line 760, in delete
    await self._state.http.delete_message(self.channel.id, self.id)
  File "/home/pi/.local/lib/python3.7/site-packages/discord/http.py", line 243, in request
    raise NotFound(r, data)
discord.errors.NotFound: 404 Not Found (error code: 10008): Unknown Message
Ignoring exception in on_message
Traceback (most recent call last):
  File "/home/pi/.local/lib/python3.7/site-packages/discord/client.py", line 312, in _run_event
    await coro(*args, **kwargs)
  File "dischat_2.py", line 141, in on_message
    await message.delete()
  File "/home/pi/.local/lib/python3.7/site-packages/discord/message.py", line 760, in delete
    await self._state.http.delete_message(self.channel.id, self.id)
  File "/home/pi/.local/lib/python3.7/site-packages/discord/http.py", line 243, in request
    raise NotFound(r, data)
discord.errors.NotFound: 404 Not Found (error code: 10008): Unknown Message
Ignoring exception in on_message
Traceback (most recent call last):
  File "/home/pi/.local/lib/python3.7/site-packages/discord/client.py", line 312, in _run_event
    await coro(*args, **kwargs)
  File "dischat_2.py", line 141, in on_message
    await message.delete()
  File "/home/pi/.local/lib/python3.7/site-packages/discord/message.py", line 760, in delete
    await self._state.http.delete_message(self.channel.id, self.id)
  File "/home/pi/.local/lib/python3.7/site-packages/discord/http.py", line 243, in request
    raise NotFound(r, data)
discord.errors.NotFound: 404 Not Found (error code: 10008): Unknown Message
Ignoring exception in on_message
Traceback (most recent call last):
  File "/home/pi/.local/lib/python3.7/site-packages/discord/client.py", line 312, in _run_event
    await coro(*args, **kwargs)
  File "dischat_2.py", line 141, in on_message
    await message.delete()
  File "/home/pi/.local/lib/python3.7/site-packages/discord/message.py", line 760, in delete
    await self._state.http.delete_message(self.channel.id, self.id)
  File "/home/pi/.local/lib/python3.7/site-packages/discord/http.py", line 243, in request
    raise NotFound(r, data)
discord.errors.NotFound: 404 Not Found (error code: 10008): Unknown Message
Ignoring exception in on_message
Traceback (most recent call last):
  File "/home/pi/.local/lib/python3.7/site-packages/discord/client.py", line 312, in _run_event
    await coro(*args, **kwargs)
  File "dischat_2.py", line 141, in on_message
    await message.delete()
  File "/home/pi/.local/lib/python3.7/site-packages/discord/message.py", line 760, in delete
    await self._state.http.delete_message(self.channel.id, self.id)
  File "/home/pi/.local/lib/python3.7/site-packages/discord/http.py", line 243, in request
    raise NotFound(r, data)
discord.errors.NotFound: 404 Not Found (error code: 10008): Unknown Message
Ignoring exception in on_message
Traceback (most recent call last):
  File "/home/pi/.local/lib/python3.7/site-packages/discord/client.py", line 312, in _run_event
    await coro(*args, **kwargs)
  File "dischat_2.py", line 141, in on_message
    await message.delete()
  File "/home/pi/.local/lib/python3.7/site-packages/discord/message.py", line 760, in delete
    await self._state.http.delete_message(self.channel.id, self.id)
  File "/home/pi/.local/lib/python3.7/site-packages/discord/http.py", line 243, in request
    raise NotFound(r, data)
discord.errors.NotFound: 404 Not Found (error code: 10008): Unknown Message
Ignoring exception in on_message
Traceback (most recent call last):
  File "/home/pi/.local/lib/python3.7/site-packages/discord/client.py", line 312, in _run_event
    await coro(*args, **kwargs)
  File "dischat_2.py", line 141, in on_message
    await message.delete()
  File "/home/pi/.local/lib/python3.7/site-packages/discord/message.py", line 760, in delete
    await self._state.http.delete_message(self.channel.id, self.id)
  File "/home/pi/.local/lib/python3.7/site-packages/discord/http.py", line 243, in request
    raise NotFound(r, data)
discord.errors.NotFound: 404 Not Found (error code: 10008): Unknown Message
Ignoring exception in on_message
Traceback (most recent call last):
  File "/home/pi/.local/lib/python3.7/site-packages/discord/client.py", line 312, in _run_event
    await coro(*args, **kwargs)
  File "dischat_2.py", line 141, in on_message
    await message.delete()
  File "/home/pi/.local/lib/python3.7/site-packages/discord/message.py", line 760, in delete
    await self._state.http.delete_message(self.channel.id, self.id)
  File "/home/pi/.local/lib/python3.7/site-packages/discord/http.py", line 243, in request
    raise NotFound(r, data)
discord.errors.NotFound: 404 Not Found (error code: 10008): Unknown Message
Ignoring exception in on_message
Traceback (most recent call last):
  File "/home/pi/.local/lib/python3.7/site-packages/discord/client.py", line 312, in _run_event
    await coro(*args, **kwargs)
  File "dischat_2.py", line 141, in on_message
    await message.delete()
  File "/home/pi/.local/lib/python3.7/site-packages/discord/message.py", line 760, in delete
    await self._state.http.delete_message(self.channel.id, self.id)
  File "/home/pi/.local/lib/python3.7/site-packages/discord/http.py", line 243, in request
    raise NotFound(r, data)
discord.errors.NotFound: 404 Not Found (error code: 10008): Unknown Message
Ignoring exception in on_message
Traceback (most recent call last):
  File "/home/pi/.local/lib/python3.7/site-packages/discord/client.py", line 312, in _run_event
    await coro(*args, **kwargs)
  File "dischat_2.py", line 141, in on_message
    await message.delete()
  File "/home/pi/.local/lib/python3.7/site-packages/discord/message.py", line 760, in delete
    await self._state.http.delete_message(self.channel.id, self.id)
  File "/home/pi/.local/lib/python3.7/site-packages/discord/http.py", line 243, in request
    raise NotFound(r, data)
discord.errors.NotFound: 404 Not Found (error code: 10008): Unknown Message
websocket connection is closing.
websocket connection is closing.
websocket connection is closing.
Traceback (most recent call last):
  File "dischat_2_w.py", line 10, in <module>
    from bs4 import BeautifulSoup
  File "/usr/lib/python3/dist-packages/bs4/__init__.py", line 34, in <module>
    from .builder import builder_registry, ParserRejectedMarkup
  File "/usr/lib/python3/dist-packages/bs4/builder/__init__.py", line 341, in <module>
    from . import _lxml
  File "/usr/lib/python3/dist-packages/bs4/builder/_lxml.py", line 16, in <module>
    from lxml import etree
  File "src/lxml/etree.pyx", line 504, in init lxml.etree
  File "/usr/lib/python3.7/re.py", line 234, in compile
    return _compile(pattern, flags)
  File "/usr/lib/python3.7/re.py", line 286, in _compile
    p = sre_compile.compile(pattern, flags)
  File "/usr/lib/python3.7/sre_compile.py", line 768, in compile
    code = _code(p, flags)
  File "/usr/lib/python3.7/sre_compile.py", line 607, in _code
    _compile(code, p.data, flags)
  File "/usr/lib/python3.7/sre_compile.py", line 148, in _compile
    _compile(code, av[2], flags)
  File "/usr/lib/python3.7/sre_compile.py", line 120, in _compile
    charset, hascased = _optimize_charset(av, iscased, tolower, fixes)
  File "/usr/lib/python3.7/sre_compile.py", line 295, in _optimize_charset
    charmap[av] = 1
KeyboardInterrupt
Ignoring exception in on_message
Traceback (most recent call last):
  File "/home/pi/.local/lib/python3.7/site-packages/discord/client.py", line 312, in _run_event
    await coro(*args, **kwargs)
  File "dischat_2_w.py", line 176, in on_message
    await message.delete()
  File "/home/pi/.local/lib/python3.7/site-packages/discord/message.py", line 760, in delete
    await self._state.http.delete_message(self.channel.id, self.id)
  File "/home/pi/.local/lib/python3.7/site-packages/discord/http.py", line 243, in request
    raise NotFound(r, data)
discord.errors.NotFound: 404 Not Found (error code: 10008): Unknown Message
Error! 지역 검색 오류!
Error! 지역 검색 오류!
Error! 지역 검색 오류!
Error! 지역 검색 오류!
Error! 지역 검색 오류!
websocket connection is closing.
websocket connection is closing.
websocket connection is closing.
Error! 지역 검색 오류!
websocket connection is closing.
websocket connection is closing.
Sending magic packet to 255.255.255.255:9 with BC:5F:F4:5C:85:B9
Ignoring exception in on_message
Traceback (most recent call last):
  File "aingbot.py", line 78, in on_message
    vc = await channel.connect()
  File "/home/pi/.local/lib/python3.7/site-packages/discord/abc.py", line 1097, in connect
    voice = VoiceClient(state=state, timeout=timeout, channel=self)
  File "/home/pi/.local/lib/python3.7/site-packages/discord/voice_client.py", line 90, in __init__
    raise RuntimeError("PyNaCl library needed in order to use voice")
RuntimeError: PyNaCl library needed in order to use voice

During handling of the above exception, another exception occurred:

Traceback (most recent call last):
  File "/home/pi/.local/lib/python3.7/site-packages/discord/client.py", line 312, in _run_event
    await coro(*args, **kwargs)
  File "aingbot.py", line 85, in on_message
    if not voice_client.is_playing():
AttributeError: 'NoneType' object has no attribute 'is_playing'
websocket connection is closing.
Sending magic packet to 255.255.255.255:9 with BC:5F:F4:5C:85:B9
websocket connection is closing.
Sending magic packet to 255.255.255.255:9 with BC:5F:F4:5C:85:B9
Sending magic packet to 255.255.255.255:9 with BC:5F:F4:5C:85:B9
Ignoring exception in on_message
Traceback (most recent call last):
  File "/home/pi/.local/lib/python3.7/site-packages/discord/client.py", line 312, in _run_event
    await coro(*args, **kwargs)
  File "dischat_2_w.py", line 185, in on_message
    await message.delete()
  File "/home/pi/.local/lib/python3.7/site-packages/discord/message.py", line 760, in delete
    await self._state.http.delete_message(self.channel.id, self.id)
  File "/home/pi/.local/lib/python3.7/site-packages/discord/http.py", line 243, in request
    raise NotFound(r, data)
discord.errors.NotFound: 404 Not Found (error code: 10008): Unknown Message
Ignoring exception in on_message
Traceback (most recent call last):
  File "/home/pi/.local/lib/python3.7/site-packages/discord/client.py", line 312, in _run_event
    await coro(*args, **kwargs)
  File "dischat_2_w.py", line 185, in on_message
    await message.delete()
  File "/home/pi/.local/lib/python3.7/site-packages/discord/message.py", line 760, in delete
    await self._state.http.delete_message(self.channel.id, self.id)
  File "/home/pi/.local/lib/python3.7/site-packages/discord/http.py", line 243, in request
    raise NotFound(r, data)
discord.errors.NotFound: 404 Not Found (error code: 10008): Unknown Message
websocket connection is closing.
Sending magic packet to 255.255.255.255:9 with BC:5F:F4:5C:85:B9
websocket connection is closing.
Sending magic packet to 255.255.255.255:9 with BC:5F:F4:5C:85:B9
Sending magic packet to 255.255.255.255:9 with BC:5F:F4:5C:85:B9
websocket connection is closing.
websocket connection is closing.
websocket connection is closing.
websocket connection is closing.
websocket connection is closing.
Ignoring exception in on_message
Traceback (most recent call last):
  File "/home/pi/.local/lib/python3.7/site-packages/discord/client.py", line 312, in _run_event
    await coro(*args, **kwargs)
  File "dischat_2_w.py", line 185, in on_message
    await message.delete()
  File "/home/pi/.local/lib/python3.7/site-packages/discord/message.py", line 760, in delete
    await self._state.http.delete_message(self.channel.id, self.id)
  File "/home/pi/.local/lib/python3.7/site-packages/discord/http.py", line 243, in request
    raise NotFound(r, data)
discord.errors.NotFound: 404 Not Found (error code: 10008): Unknown Message
websocket connection is closing.
Ignoring exception in on_message
Traceback (most recent call last):
  File "/home/pi/.local/lib/python3.7/site-packages/discord/client.py", line 312, in _run_event
    await coro(*args, **kwargs)
  File "aingbot.py", line 75, in on_message
    channel = message.author.voice.channel
AttributeError: 'NoneType' object has no attribute 'channel'
Ignoring exception in on_message
Traceback (most recent call last):
  File "/home/pi/.local/lib/python3.7/site-packages/discord/client.py", line 312, in _run_event
    await coro(*args, **kwargs)
  File "aingbot.py", line 75, in on_message
    channel = message.author.voice.channel
AttributeError: 'NoneType' object has no attribute 'channel'
websocket connection is closing.
websocket connection is closing.
websocket connection is closing.
websocket connection is closing.
websocket connection is closing.
websocket connection is closing.
websocket connection is closing.
python3: can't open file 'dischat_2_': [Errno 2] No such file or directory
websocket connection is closing.
Ignoring exception in on_message
Traceback (most recent call last):
  File "aingbot.py", line 78, in on_message
    vc = await channel.connect()
  File "/home/pi/.local/lib/python3.7/site-packages/discord/abc.py", line 1097, in connect
    voice = VoiceClient(state=state, timeout=timeout, channel=self)
  File "/home/pi/.local/lib/python3.7/site-packages/discord/voice_client.py", line 90, in __init__
    raise RuntimeError("PyNaCl library needed in order to use voice")
RuntimeError: PyNaCl library needed in order to use voice

During handling of the above exception, another exception occurred:

Traceback (most recent call last):
  File "/home/pi/.local/lib/python3.7/site-packages/discord/client.py", line 312, in _run_event
    await coro(*args, **kwargs)
  File "aingbot.py", line 85, in on_message
    if not voice_client.is_playing():
AttributeError: 'NoneType' object has no attribute 'is_playing'
Ignoring exception in on_message
Traceback (most recent call last):
  File "aingbot.py", line 78, in on_message
    vc = await channel.connect()
  File "/home/pi/.local/lib/python3.7/site-packages/discord/abc.py", line 1097, in connect
    voice = VoiceClient(state=state, timeout=timeout, channel=self)
  File "/home/pi/.local/lib/python3.7/site-packages/discord/voice_client.py", line 90, in __init__
    raise RuntimeError("PyNaCl library needed in order to use voice")
RuntimeError: PyNaCl library needed in order to use voice

During handling of the above exception, another exception occurred:

Traceback (most recent call last):
  File "/home/pi/.local/lib/python3.7/site-packages/discord/client.py", line 312, in _run_event
    await coro(*args, **kwargs)
  File "aingbot.py", line 85, in on_message
    if not voice_client.is_playing():
AttributeError: 'NoneType' object has no attribute 'is_playing'
Ignoring exception in on_message
Traceback (most recent call last):
  File "aingbot.py", line 78, in on_message
    vc = await channel.connect()
  File "/home/pi/.local/lib/python3.7/site-packages/discord/abc.py", line 1097, in connect
    voice = VoiceClient(state=state, timeout=timeout, channel=self)
  File "/home/pi/.local/lib/python3.7/site-packages/discord/voice_client.py", line 90, in __init__
    raise RuntimeError("PyNaCl library needed in order to use voice")
RuntimeError: PyNaCl library needed in order to use voice

During handling of the above exception, another exception occurred:

Traceback (most recent call last):
  File "/home/pi/.local/lib/python3.7/site-packages/discord/client.py", line 312, in _run_event
    await coro(*args, **kwargs)
  File "aingbot.py", line 85, in on_message
    if not voice_client.is_playing():
AttributeError: 'NoneType' object has no attribute 'is_playing'
Ignoring exception in on_message
Traceback (most recent call last):
  File "aingbot.py", line 78, in on_message
    vc = await channel.connect()
  File "/home/pi/.local/lib/python3.7/site-packages/discord/abc.py", line 1097, in connect
    voice = VoiceClient(state=state, timeout=timeout, channel=self)
  File "/home/pi/.local/lib/python3.7/site-packages/discord/voice_client.py", line 90, in __init__
    raise RuntimeError("PyNaCl library needed in order to use voice")
RuntimeError: PyNaCl library needed in order to use voice

During handling of the above exception, another exception occurred:

Traceback (most recent call last):
  File "/home/pi/.local/lib/python3.7/site-packages/discord/client.py", line 312, in _run_event
    await coro(*args, **kwargs)
  File "aingbot.py", line 85, in on_message
    if not voice_client.is_playing():
AttributeError: 'NoneType' object has no attribute 'is_playing'
Ignoring exception in on_message
Traceback (most recent call last):
  File "aingbot.py", line 78, in on_message
    vc = await channel.connect()
  File "/home/pi/.local/lib/python3.7/site-packages/discord/abc.py", line 1097, in connect
    voice = VoiceClient(state=state, timeout=timeout, channel=self)
  File "/home/pi/.local/lib/python3.7/site-packages/discord/voice_client.py", line 90, in __init__
    raise RuntimeError("PyNaCl library needed in order to use voice")
RuntimeError: PyNaCl library needed in order to use voice

During handling of the above exception, another exception occurred:

Traceback (most recent call last):
  File "/home/pi/.local/lib/python3.7/site-packages/discord/client.py", line 312, in _run_event
    await coro(*args, **kwargs)
  File "aingbot.py", line 85, in on_message
    if not voice_client.is_playing():
AttributeError: 'NoneType' object has no attribute 'is_playing'
Ignoring exception in on_message
Traceback (most recent call last):
  File "aingbot.py", line 78, in on_message
    vc = await channel.connect()
  File "/home/pi/.local/lib/python3.7/site-packages/discord/abc.py", line 1097, in connect
    voice = VoiceClient(state=state, timeout=timeout, channel=self)
  File "/home/pi/.local/lib/python3.7/site-packages/discord/voice_client.py", line 90, in __init__
    raise RuntimeError("PyNaCl library needed in order to use voice")
RuntimeError: PyNaCl library needed in order to use voice

During handling of the above exception, another exception occurred:

Traceback (most recent call last):
  File "/home/pi/.local/lib/python3.7/site-packages/discord/client.py", line 312, in _run_event
    await coro(*args, **kwargs)
  File "aingbot.py", line 85, in on_message
    if not voice_client.is_playing():
AttributeError: 'NoneType' object has no attribute 'is_playing'
Ignoring exception in on_message
Traceback (most recent call last):
  File "aingbot.py", line 78, in on_message
    vc = await channel.connect()
  File "/home/pi/.local/lib/python3.7/site-packages/discord/abc.py", line 1097, in connect
    voice = VoiceClient(state=state, timeout=timeout, channel=self)
  File "/home/pi/.local/lib/python3.7/site-packages/discord/voice_client.py", line 90, in __init__
    raise RuntimeError("PyNaCl library needed in order to use voice")
RuntimeError: PyNaCl library needed in order to use voice

During handling of the above exception, another exception occurred:

Traceback (most recent call last):
  File "/home/pi/.local/lib/python3.7/site-packages/discord/client.py", line 312, in _run_event
    await coro(*args, **kwargs)
  File "aingbot.py", line 85, in on_message
    if not voice_client.is_playing():
AttributeError: 'NoneType' object has no attribute 'is_playing'
Ignoring exception in on_message
Traceback (most recent call last):
  File "aingbot.py", line 78, in on_message
    vc = await channel.connect()
  File "/home/pi/.local/lib/python3.7/site-packages/discord/abc.py", line 1097, in connect
    voice = VoiceClient(state=state, timeout=timeout, channel=self)
  File "/home/pi/.local/lib/python3.7/site-packages/discord/voice_client.py", line 90, in __init__
    raise RuntimeError("PyNaCl library needed in order to use voice")
RuntimeError: PyNaCl library needed in order to use voice

During handling of the above exception, another exception occurred:

Traceback (most recent call last):
  File "/home/pi/.local/lib/python3.7/site-packages/discord/client.py", line 312, in _run_event
    await coro(*args, **kwargs)
  File "aingbot.py", line 85, in on_message
    if not voice_client.is_playing():
AttributeError: 'NoneType' object has no attribute 'is_playing'
Ignoring exception in on_message
Traceback (most recent call last):
  File "aingbot.py", line 78, in on_message
    vc = await channel.connect()
  File "/home/pi/.local/lib/python3.7/site-packages/discord/abc.py", line 1097, in connect
    voice = VoiceClient(state=state, timeout=timeout, channel=self)
  File "/home/pi/.local/lib/python3.7/site-packages/discord/voice_client.py", line 90, in __init__
    raise RuntimeError("PyNaCl library needed in order to use voice")
RuntimeError: PyNaCl library needed in order to use voice

During handling of the above exception, another exception occurred:

Traceback (most recent call last):
  File "/home/pi/.local/lib/python3.7/site-packages/discord/client.py", line 312, in _run_event
    await coro(*args, **kwargs)
  File "aingbot.py", line 85, in on_message
    if not voice_client.is_playing():
AttributeError: 'NoneType' object has no attribute 'is_playing'
Ignoring exception in on_message
Traceback (most recent call last):
  File "aingbot.py", line 78, in on_message
    vc = await channel.connect()
  File "/home/pi/.local/lib/python3.7/site-packages/discord/abc.py", line 1097, in connect
    voice = VoiceClient(state=state, timeout=timeout, channel=self)
  File "/home/pi/.local/lib/python3.7/site-packages/discord/voice_client.py", line 90, in __init__
    raise RuntimeError("PyNaCl library needed in order to use voice")
RuntimeError: PyNaCl library needed in order to use voice

During handling of the above exception, another exception occurred:

Traceback (most recent call last):
  File "/home/pi/.local/lib/python3.7/site-packages/discord/client.py", line 312, in _run_event
    await coro(*args, **kwargs)
  File "aingbot.py", line 85, in on_message
    if not voice_client.is_playing():
AttributeError: 'NoneType' object has no attribute 'is_playing'
Ignoring exception in on_message
Traceback (most recent call last):
  File "aingbot.py", line 78, in on_message
    vc = await channel.connect()
  File "/home/pi/.local/lib/python3.7/site-packages/discord/abc.py", line 1097, in connect
    voice = VoiceClient(state=state, timeout=timeout, channel=self)
  File "/home/pi/.local/lib/python3.7/site-packages/discord/voice_client.py", line 90, in __init__
    raise RuntimeError("PyNaCl library needed in order to use voice")
RuntimeError: PyNaCl library needed in order to use voice

During handling of the above exception, another exception occurred:

Traceback (most recent call last):
  File "/home/pi/.local/lib/python3.7/site-packages/discord/client.py", line 312, in _run_event
    await coro(*args, **kwargs)
  File "aingbot.py", line 85, in on_message
    if not voice_client.is_playing():
AttributeError: 'NoneType' object has no attribute 'is_playing'
Ignoring exception in on_message
Traceback (most recent call last):
  File "aingbot.py", line 78, in on_message
    vc = await channel.connect()
  File "/home/pi/.local/lib/python3.7/site-packages/discord/abc.py", line 1097, in connect
    voice = VoiceClient(state=state, timeout=timeout, channel=self)
  File "/home/pi/.local/lib/python3.7/site-packages/discord/voice_client.py", line 90, in __init__
    raise RuntimeError("PyNaCl library needed in order to use voice")
RuntimeError: PyNaCl library needed in order to use voice

During handling of the above exception, another exception occurred:

Traceback (most recent call last):
  File "/home/pi/.local/lib/python3.7/site-packages/discord/client.py", line 312, in _run_event
    await coro(*args, **kwargs)
  File "aingbot.py", line 85, in on_message
    if not voice_client.is_playing():
AttributeError: 'NoneType' object has no attribute 'is_playing'
Ignoring exception in on_message
Traceback (most recent call last):
  File "aingbot.py", line 78, in on_message
    vc = await channel.connect()
  File "/home/pi/.local/lib/python3.7/site-packages/discord/abc.py", line 1097, in connect
    voice = VoiceClient(state=state, timeout=timeout, channel=self)
  File "/home/pi/.local/lib/python3.7/site-packages/discord/voice_client.py", line 90, in __init__
    raise RuntimeError("PyNaCl library needed in order to use voice")
RuntimeError: PyNaCl library needed in order to use voice

During handling of the above exception, another exception occurred:

Traceback (most recent call last):
  File "/home/pi/.local/lib/python3.7/site-packages/discord/client.py", line 312, in _run_event
    await coro(*args, **kwargs)
  File "aingbot.py", line 85, in on_message
    if not voice_client.is_playing():
AttributeError: 'NoneType' object has no attribute 'is_playing'
websocket connection is closing.
Ignoring exception in on_message
Traceback (most recent call last):
  File "/home/pi/.local/lib/python3.7/site-packages/discord/client.py", line 312, in _run_event
    await coro(*args, **kwargs)
  File "dischat_2_w.py", line 185, in on_message
    await message.delete()
  File "/home/pi/.local/lib/python3.7/site-packages/discord/message.py", line 760, in delete
    await self._state.http.delete_message(self.channel.id, self.id)
  File "/home/pi/.local/lib/python3.7/site-packages/discord/http.py", line 243, in request
    raise NotFound(r, data)
discord.errors.NotFound: 404 Not Found (error code: 10008): Unknown Message
Ignoring exception in on_message
Traceback (most recent call last):
  File "/home/pi/.local/lib/python3.7/site-packages/discord/client.py", line 312, in _run_event
    await coro(*args, **kwargs)
  File "dischat_2_w.py", line 185, in on_message
    await message.delete()
  File "/home/pi/.local/lib/python3.7/site-packages/discord/message.py", line 760, in delete
    await self._state.http.delete_message(self.channel.id, self.id)
  File "/home/pi/.local/lib/python3.7/site-packages/discord/http.py", line 243, in request
    raise NotFound(r, data)
discord.errors.NotFound: 404 Not Found (error code: 10008): Unknown Message
Ignoring exception in on_message
Traceback (most recent call last):
  File "/home/pi/.local/lib/python3.7/site-packages/discord/client.py", line 312, in _run_event
    await coro(*args, **kwargs)
  File "dischat_2_w.py", line 185, in on_message
    await message.delete()
  File "/home/pi/.local/lib/python3.7/site-packages/discord/message.py", line 760, in delete
    await self._state.http.delete_message(self.channel.id, self.id)
  File "/home/pi/.local/lib/python3.7/site-packages/discord/http.py", line 243, in request
    raise NotFound(r, data)
discord.errors.NotFound: 404 Not Found (error code: 10008): Unknown Message
websocket connection is closing.
websocket connection is closing.
websocket connection is closing.
Error! 지역 검색 오류!
websocket connection is closing.
websocket connection is closing.
websocket connection is closing.
websocket connection is closing.
Error! 지역 검색 오류!
Error! 지역 검색 오류!
Traceback (most recent call last):
  File "dischat_2_w.py", line 12, in <module>
    import requests
  File "/usr/lib/python3/dist-packages/requests/__init__.py", line 43, in <module>
    import urllib3
  File "/usr/lib/python3/dist-packages/urllib3/__init__.py", line 8, in <module>
    from .connectionpool import (
  File "/usr/lib/python3/dist-packages/urllib3/connectionpool.py", line 29, in <module>
    from .connection import (
  File "/usr/lib/python3/dist-packages/urllib3/connection.py", line 38, in <module>
    from .util.ssl_ import (
  File "/usr/lib/python3/dist-packages/urllib3/util/__init__.py", line 22, in <module>
    from .url import (
  File "/usr/lib/python3/dist-packages/urllib3/util/url.py", line 14, in <module>
    class Url(namedtuple('Url', url_attrs)):
  File "/usr/lib/python3.7/collections/__init__.py", line 394, in namedtuple
    s = f'def __new__(_cls, {arg_list}): return _tuple_new(_cls, ({arg_list}))'
KeyboardInterrupt
websocket connection is closing.
websocket connection is closing.
websocket connection is closing.
python3: can't open file 'dischat_2_2': [Errno 2] No such file or directory
websocket connection is closing.
Traceback (most recent call last):
  File "dischat_2_w.py", line 4, in <module>
    import discord
  File "/home/pi/.local/lib/python3.7/site-packages/discord/__init__.py", line 25, in <module>
    from .client import Client
  File "/home/pi/.local/lib/python3.7/site-packages/discord/client.py", line 34, in <module>
    import aiohttp
  File "/home/pi/.local/lib/python3.7/site-packages/aiohttp/__init__.py", line 6, in <module>
    from .client import BaseConnector as BaseConnector
  File "/home/pi/.local/lib/python3.7/site-packages/aiohttp/client.py", line 32, in <module>
    from . import hdrs, http, payload
  File "/home/pi/.local/lib/python3.7/site-packages/aiohttp/http.py", line 1, in <module>
    import http.server
  File "/usr/lib/python3.7/http/server.py", line 96, in <module>
    import mimetypes
  File "/usr/lib/python3.7/mimetypes.py", line 31, in <module>
    import winreg as _winreg
  File "<frozen importlib._bootstrap>", line 983, in _find_and_load
  File "<frozen importlib._bootstrap>", line 963, in _find_and_load_unlocked
  File "<frozen importlib._bootstrap>", line 906, in _find_spec
  File "<frozen importlib._bootstrap_external>", line 1280, in find_spec
  File "<frozen importlib._bootstrap_external>", line 1252, in _get_spec
  File "<frozen importlib._bootstrap_external>", line 1392, in find_spec
KeyboardInterrupt
Ignoring exception in on_message
Traceback (most recent call last):
  File "/home/pi/.local/lib/python3.7/site-packages/discord/client.py", line 312, in _run_event
    await coro(*args, **kwargs)
  File "dischat_2_w.py", line 112, in on_message
    school_excel = maria_python.exe_sql(int(message_contant[9:]))
ValueError: invalid literal for int() with base 10: '띄고+요일 숫자?)'
Ignoring exception in on_message
Traceback (most recent call last):
  File "/home/pi/.local/lib/python3.7/site-packages/discord/client.py", line 312, in _run_event
    await coro(*args, **kwargs)
  File "dischat_2_w.py", line 112, in on_message
    school_excel = maria_python.exe_sql(int(message_contant[9:]))
ValueError: invalid literal for int() with base 10: '목요일6'
Ignoring exception in on_message
Traceback (most recent call last):
  File "/home/pi/.local/lib/python3.7/site-packages/discord/client.py", line 312, in _run_event
    await coro(*args, **kwargs)
  File "dischat_2_w.py", line 217, in on_message
    await message.delete()
  File "/home/pi/.local/lib/python3.7/site-packages/discord/message.py", line 760, in delete
    await self._state.http.delete_message(self.channel.id, self.id)
  File "/home/pi/.local/lib/python3.7/site-packages/discord/http.py", line 243, in request
    raise NotFound(r, data)
discord.errors.NotFound: 404 Not Found (error code: 10008): Unknown Message
websocket connection is closing.
websocket connection is closing.
Ignoring exception in on_message
Traceback (most recent call last):
  File "/home/pi/.local/lib/python3.7/site-packages/discord/client.py", line 312, in _run_event
    await coro(*args, **kwargs)
  File "aingbot.py", line 73, in on_message
    await message.channel.send(file=discord.File('./pic/aing_{}.png'.format(str(random.randint(0,6)))))
  File "/home/pi/.local/lib/python3.7/site-packages/discord/abc.py", line 873, in send
    content=content, tts=tts, embed=embed, nonce=nonce)
  File "/home/pi/.local/lib/python3.7/site-packages/discord/http.py", line 185, in request
    async with self.__session.request(method, url, **kwargs) as r:
  File "/home/pi/.local/lib/python3.7/site-packages/aiohttp/client.py", line 1012, in __aenter__
    self._resp = await self._coro
  File "/home/pi/.local/lib/python3.7/site-packages/aiohttp/client.py", line 504, in _request
    await resp.start(conn)
  File "/home/pi/.local/lib/python3.7/site-packages/aiohttp/client_reqrep.py", line 847, in start
    message, payload = await self._protocol.read()  # type: ignore  # noqa
  File "/home/pi/.local/lib/python3.7/site-packages/aiohttp/streams.py", line 591, in read
    await self._waiter
aiohttp.client_exceptions.ClientOSError: [Errno 32] Broken pipe
Ignoring exception in on_message
Traceback (most recent call last):
  File "/home/pi/.local/lib/python3.7/site-packages/discord/client.py", line 312, in _run_event
    await coro(*args, **kwargs)
  File "aingbot.py", line 73, in on_message
    await message.channel.send(file=discord.File('./pic/aing_{}.png'.format(str(random.randint(0,6)))))
  File "/home/pi/.local/lib/python3.7/site-packages/discord/abc.py", line 873, in send
    content=content, tts=tts, embed=embed, nonce=nonce)
  File "/home/pi/.local/lib/python3.7/site-packages/discord/http.py", line 185, in request
    async with self.__session.request(method, url, **kwargs) as r:
  File "/home/pi/.local/lib/python3.7/site-packages/aiohttp/client.py", line 1012, in __aenter__
    self._resp = await self._coro
  File "/home/pi/.local/lib/python3.7/site-packages/aiohttp/client.py", line 504, in _request
    await resp.start(conn)
  File "/home/pi/.local/lib/python3.7/site-packages/aiohttp/client_reqrep.py", line 847, in start
    message, payload = await self._protocol.read()  # type: ignore  # noqa
  File "/home/pi/.local/lib/python3.7/site-packages/aiohttp/streams.py", line 591, in read
    await self._waiter
aiohttp.client_exceptions.ClientOSError: [Errno 32] Broken pipe
SSL error in data received
protocol: <asyncio.sslproto.SSLProtocol object at 0x73e5f6f0>
transport: <_SelectorSocketTransport fd=7 read=polling write=<idle, bufsize=0>>
Traceback (most recent call last):
  File "/usr/lib/python3.7/asyncio/sslproto.py", line 526, in data_received
    ssldata, appdata = self._sslpipe.feed_ssldata(data)
  File "/usr/lib/python3.7/asyncio/sslproto.py", line 207, in feed_ssldata
    self._sslobj.unwrap()
  File "/usr/lib/python3.7/ssl.py", line 767, in unwrap
    return self._sslobj.shutdown()
ssl.SSLError: [SSL: KRB5_S_INIT] application data after close notify (_ssl.c:2609)
Traceback (most recent call last):
  File "aingbot.py", line 3, in <module>
    import discord
  File "/home/pi/.local/lib/python3.7/site-packages/discord/__init__.py", line 25, in <module>
    from .client import Client
  File "/home/pi/.local/lib/python3.7/site-packages/discord/client.py", line 34, in <module>
    import aiohttp
  File "/home/pi/.local/lib/python3.7/site-packages/aiohttp/__init__.py", line 6, in <module>
    from .client import BaseConnector as BaseConnector
  File "/home/pi/.local/lib/python3.7/site-packages/aiohttp/client.py", line 32, in <module>
    from . import hdrs, http, payload
  File "/home/pi/.local/lib/python3.7/site-packages/aiohttp/http.py", line 7, in <module>
    from .http_parser import HeadersParser as HeadersParser
  File "/home/pi/.local/lib/python3.7/site-packages/aiohttp/http_parser.py", line 15, in <module>
    from .helpers import NO_EXTENSIONS, BaseTimerContext
  File "/home/pi/.local/lib/python3.7/site-packages/aiohttp/helpers.py", line 41, in <module>
    from urllib.request import getproxies
  File "/usr/lib/python3.7/urllib/request.py", line 940, in <module>
    class AbstractBasicAuthHandler:
  File "/usr/lib/python3.7/urllib/request.py", line 955, in AbstractBasicAuthHandler
    re.I)
  File "/usr/lib/python3.7/re.py", line 234, in compile
    return _compile(pattern, flags)
  File "/usr/lib/python3.7/re.py", line 286, in _compile
    p = sre_compile.compile(pattern, flags)
  File "/usr/lib/python3.7/sre_compile.py", line 764, in compile
    p = sre_parse.parse(p, flags)
  File "/usr/lib/python3.7/sre_parse.py", line 930, in parse
    p = _parse_sub(source, pattern, flags & SRE_FLAG_VERBOSE, 0)
  File "/usr/lib/python3.7/sre_parse.py", line 426, in _parse_sub
    not nested and not items))
  File "/usr/lib/python3.7/sre_parse.py", line 816, in _parse
    p = _parse_sub(source, state, sub_verbose, nested + 1)
  File "/usr/lib/python3.7/sre_parse.py", line 426, in _parse_sub
    not nested and not items))
  File "/usr/lib/python3.7/sre_parse.py", line 516, in _parse
    set = []
KeyboardInterrupt
Ignoring exception in on_message
Traceback (most recent call last):
  File "/home/pi/.local/lib/python3.7/site-packages/discord/client.py", line 312, in _run_event
    await coro(*args, **kwargs)
  File "aingbot.py", line 73, in on_message
    await message.channel.send(file=discord.File('./pic/aing_{}.png'.format(str(random.randint(0,6)))))
  File "/home/pi/.local/lib/python3.7/site-packages/discord/abc.py", line 873, in send
    content=content, tts=tts, embed=embed, nonce=nonce)
  File "/home/pi/.local/lib/python3.7/site-packages/discord/http.py", line 185, in request
    async with self.__session.request(method, url, **kwargs) as r:
  File "/home/pi/.local/lib/python3.7/site-packages/aiohttp/client.py", line 1012, in __aenter__
    self._resp = await self._coro
  File "/home/pi/.local/lib/python3.7/site-packages/aiohttp/client.py", line 504, in _request
    await resp.start(conn)
  File "/home/pi/.local/lib/python3.7/site-packages/aiohttp/client_reqrep.py", line 847, in start
    message, payload = await self._protocol.read()  # type: ignore  # noqa
  File "/home/pi/.local/lib/python3.7/site-packages/aiohttp/streams.py", line 591, in read
    await self._waiter
aiohttp.client_exceptions.ClientOSError: [Errno 32] Broken pipe
Ignoring exception in on_message
Traceback (most recent call last):
  File "/home/pi/.local/lib/python3.7/site-packages/discord/client.py", line 312, in _run_event
    await coro(*args, **kwargs)
  File "aingbot.py", line 75, in on_message
    channel = message.author.voice.channel
AttributeError: 'NoneType' object has no attribute 'channel'
Ignoring exception in on_message
Traceback (most recent call last):
  File "aingbot.py", line 78, in on_message
    vc = await channel.connect()
  File "/home/pi/.local/lib/python3.7/site-packages/discord/abc.py", line 1097, in connect
    voice = VoiceClient(state=state, timeout=timeout, channel=self)
  File "/home/pi/.local/lib/python3.7/site-packages/discord/voice_client.py", line 90, in __init__
    raise RuntimeError("PyNaCl library needed in order to use voice")
RuntimeError: PyNaCl library needed in order to use voice

During handling of the above exception, another exception occurred:

Traceback (most recent call last):
  File "/home/pi/.local/lib/python3.7/site-packages/discord/client.py", line 312, in _run_event
    await coro(*args, **kwargs)
  File "aingbot.py", line 85, in on_message
    if not voice_client.is_playing():
AttributeError: 'NoneType' object has no attribute 'is_playing'
Ignoring exception in on_message
Traceback (most recent call last):
  File "aingbot.py", line 78, in on_message
    vc = await channel.connect()
  File "/home/pi/.local/lib/python3.7/site-packages/discord/abc.py", line 1097, in connect
    voice = VoiceClient(state=state, timeout=timeout, channel=self)
  File "/home/pi/.local/lib/python3.7/site-packages/discord/voice_client.py", line 90, in __init__
    raise RuntimeError("PyNaCl library needed in order to use voice")
RuntimeError: PyNaCl library needed in order to use voice

During handling of the above exception, another exception occurred:

Traceback (most recent call last):
  File "/home/pi/.local/lib/python3.7/site-packages/discord/client.py", line 312, in _run_event
    await coro(*args, **kwargs)
  File "aingbot.py", line 85, in on_message
    if not voice_client.is_playing():
AttributeError: 'NoneType' object has no attribute 'is_playing'
Ignoring exception in on_message
Traceback (most recent call last):
  File "aingbot.py", line 78, in on_message
    vc = await channel.connect()
  File "/home/pi/.local/lib/python3.7/site-packages/discord/abc.py", line 1097, in connect
    voice = VoiceClient(state=state, timeout=timeout, channel=self)
  File "/home/pi/.local/lib/python3.7/site-packages/discord/voice_client.py", line 90, in __init__
    raise RuntimeError("PyNaCl library needed in order to use voice")
RuntimeError: PyNaCl library needed in order to use voice

During handling of the above exception, another exception occurred:

Traceback (most recent call last):
  File "/home/pi/.local/lib/python3.7/site-packages/discord/client.py", line 312, in _run_event
    await coro(*args, **kwargs)
  File "aingbot.py", line 85, in on_message
    if not voice_client.is_playing():
AttributeError: 'NoneType' object has no attribute 'is_playing'
Ignoring exception in on_message
Traceback (most recent call last):
  File "aingbot.py", line 78, in on_message
    vc = await channel.connect()
  File "/home/pi/.local/lib/python3.7/site-packages/discord/abc.py", line 1097, in connect
    voice = VoiceClient(state=state, timeout=timeout, channel=self)
  File "/home/pi/.local/lib/python3.7/site-packages/discord/voice_client.py", line 90, in __init__
    raise RuntimeError("PyNaCl library needed in order to use voice")
RuntimeError: PyNaCl library needed in order to use voice

During handling of the above exception, another exception occurred:

Traceback (most recent call last):
  File "/home/pi/.local/lib/python3.7/site-packages/discord/client.py", line 312, in _run_event
    await coro(*args, **kwargs)
  File "aingbot.py", line 85, in on_message
    if not voice_client.is_playing():
AttributeError: 'NoneType' object has no attribute 'is_playing'
Ignoring exception in on_message
Traceback (most recent call last):
  File "aingbot.py", line 78, in on_message
    vc = await channel.connect()
  File "/home/pi/.local/lib/python3.7/site-packages/discord/abc.py", line 1097, in connect
    voice = VoiceClient(state=state, timeout=timeout, channel=self)
  File "/home/pi/.local/lib/python3.7/site-packages/discord/voice_client.py", line 90, in __init__
    raise RuntimeError("PyNaCl library needed in order to use voice")
RuntimeError: PyNaCl library needed in order to use voice

During handling of the above exception, another exception occurred:

Traceback (most recent call last):
  File "/home/pi/.local/lib/python3.7/site-packages/discord/client.py", line 312, in _run_event
    await coro(*args, **kwargs)
  File "aingbot.py", line 85, in on_message
    if not voice_client.is_playing():
AttributeError: 'NoneType' object has no attribute 'is_playing'
Ignoring exception in on_message
Traceback (most recent call last):
  File "aingbot.py", line 78, in on_message
    vc = await channel.connect()
  File "/home/pi/.local/lib/python3.7/site-packages/discord/abc.py", line 1097, in connect
    voice = VoiceClient(state=state, timeout=timeout, channel=self)
  File "/home/pi/.local/lib/python3.7/site-packages/discord/voice_client.py", line 90, in __init__
    raise RuntimeError("PyNaCl library needed in order to use voice")
RuntimeError: PyNaCl library needed in order to use voice

During handling of the above exception, another exception occurred:

Traceback (most recent call last):
  File "/home/pi/.local/lib/python3.7/site-packages/discord/client.py", line 312, in _run_event
    await coro(*args, **kwargs)
  File "aingbot.py", line 85, in on_message
    if not voice_client.is_playing():
AttributeError: 'NoneType' object has no attribute 'is_playing'
Ignoring exception in on_message
Traceback (most recent call last):
  File "aingbot.py", line 78, in on_message
    vc = await channel.connect()
  File "/home/pi/.local/lib/python3.7/site-packages/discord/abc.py", line 1097, in connect
    voice = VoiceClient(state=state, timeout=timeout, channel=self)
  File "/home/pi/.local/lib/python3.7/site-packages/discord/voice_client.py", line 90, in __init__
    raise RuntimeError("PyNaCl library needed in order to use voice")
RuntimeError: PyNaCl library needed in order to use voice

During handling of the above exception, another exception occurred:

Traceback (most recent call last):
  File "/home/pi/.local/lib/python3.7/site-packages/discord/client.py", line 312, in _run_event
    await coro(*args, **kwargs)
  File "aingbot.py", line 85, in on_message
    if not voice_client.is_playing():
AttributeError: 'NoneType' object has no attribute 'is_playing'
Ignoring exception in on_message
Traceback (most recent call last):
  File "aingbot.py", line 78, in on_message
    vc = await channel.connect()
  File "/home/pi/.local/lib/python3.7/site-packages/discord/abc.py", line 1097, in connect
    voice = VoiceClient(state=state, timeout=timeout, channel=self)
  File "/home/pi/.local/lib/python3.7/site-packages/discord/voice_client.py", line 90, in __init__
    raise RuntimeError("PyNaCl library needed in order to use voice")
RuntimeError: PyNaCl library needed in order to use voice

During handling of the above exception, another exception occurred:

Traceback (most recent call last):
  File "/home/pi/.local/lib/python3.7/site-packages/discord/client.py", line 312, in _run_event
    await coro(*args, **kwargs)
  File "aingbot.py", line 85, in on_message
    if not voice_client.is_playing():
AttributeError: 'NoneType' object has no attribute 'is_playing'
Ignoring exception in on_message
Traceback (most recent call last):
  File "aingbot.py", line 78, in on_message
    vc = await channel.connect()
  File "/home/pi/.local/lib/python3.7/site-packages/discord/abc.py", line 1097, in connect
    voice = VoiceClient(state=state, timeout=timeout, channel=self)
  File "/home/pi/.local/lib/python3.7/site-packages/discord/voice_client.py", line 90, in __init__
    raise RuntimeError("PyNaCl library needed in order to use voice")
RuntimeError: PyNaCl library needed in order to use voice

During handling of the above exception, another exception occurred:

Traceback (most recent call last):
  File "/home/pi/.local/lib/python3.7/site-packages/discord/client.py", line 312, in _run_event
    await coro(*args, **kwargs)
  File "aingbot.py", line 85, in on_message
    if not voice_client.is_playing():
AttributeError: 'NoneType' object has no attribute 'is_playing'
Ignoring exception in on_message
Traceback (most recent call last):
  File "aingbot.py", line 78, in on_message
    vc = await channel.connect()
  File "/home/pi/.local/lib/python3.7/site-packages/discord/abc.py", line 1097, in connect
    voice = VoiceClient(state=state, timeout=timeout, channel=self)
  File "/home/pi/.local/lib/python3.7/site-packages/discord/voice_client.py", line 90, in __init__
    raise RuntimeError("PyNaCl library needed in order to use voice")
RuntimeError: PyNaCl library needed in order to use voice

During handling of the above exception, another exception occurred:

Traceback (most recent call last):
  File "/home/pi/.local/lib/python3.7/site-packages/discord/client.py", line 312, in _run_event
    await coro(*args, **kwargs)
  File "aingbot.py", line 85, in on_message
    if not voice_client.is_playing():
AttributeError: 'NoneType' object has no attribute 'is_playing'
Ignoring exception in on_message
Traceback (most recent call last):
  File "aingbot.py", line 78, in on_message
    vc = await channel.connect()
  File "/home/pi/.local/lib/python3.7/site-packages/discord/abc.py", line 1097, in connect
    voice = VoiceClient(state=state, timeout=timeout, channel=self)
  File "/home/pi/.local/lib/python3.7/site-packages/discord/voice_client.py", line 90, in __init__
    raise RuntimeError("PyNaCl library needed in order to use voice")
RuntimeError: PyNaCl library needed in order to use voice

During handling of the above exception, another exception occurred:

Traceback (most recent call last):
  File "/home/pi/.local/lib/python3.7/site-packages/discord/client.py", line 312, in _run_event
    await coro(*args, **kwargs)
  File "aingbot.py", line 85, in on_message
    if not voice_client.is_playing():
AttributeError: 'NoneType' object has no attribute 'is_playing'
Ignoring exception in on_message
Traceback (most recent call last):
  File "aingbot.py", line 78, in on_message
    vc = await channel.connect()
  File "/home/pi/.local/lib/python3.7/site-packages/discord/abc.py", line 1097, in connect
    voice = VoiceClient(state=state, timeout=timeout, channel=self)
  File "/home/pi/.local/lib/python3.7/site-packages/discord/voice_client.py", line 90, in __init__
    raise RuntimeError("PyNaCl library needed in order to use voice")
RuntimeError: PyNaCl library needed in order to use voice

During handling of the above exception, another exception occurred:

Traceback (most recent call last):
  File "/home/pi/.local/lib/python3.7/site-packages/discord/client.py", line 312, in _run_event
    await coro(*args, **kwargs)
  File "aingbot.py", line 85, in on_message
    if not voice_client.is_playing():
AttributeError: 'NoneType' object has no attribute 'is_playing'
Ignoring exception in on_message
Traceback (most recent call last):
  File "aingbot.py", line 78, in on_message
    vc = await channel.connect()
  File "/home/pi/.local/lib/python3.7/site-packages/discord/abc.py", line 1097, in connect
    voice = VoiceClient(state=state, timeout=timeout, channel=self)
  File "/home/pi/.local/lib/python3.7/site-packages/discord/voice_client.py", line 90, in __init__
    raise RuntimeError("PyNaCl library needed in order to use voice")
RuntimeError: PyNaCl library needed in order to use voice

During handling of the above exception, another exception occurred:

Traceback (most recent call last):
  File "/home/pi/.local/lib/python3.7/site-packages/discord/client.py", line 312, in _run_event
    await coro(*args, **kwargs)
  File "aingbot.py", line 85, in on_message
    if not voice_client.is_playing():
AttributeError: 'NoneType' object has no attribute 'is_playing'
Ignoring exception in on_message
Traceback (most recent call last):
  File "aingbot.py", line 78, in on_message
    vc = await channel.connect()
  File "/home/pi/.local/lib/python3.7/site-packages/discord/abc.py", line 1097, in connect
    voice = VoiceClient(state=state, timeout=timeout, channel=self)
  File "/home/pi/.local/lib/python3.7/site-packages/discord/voice_client.py", line 90, in __init__
    raise RuntimeError("PyNaCl library needed in order to use voice")
RuntimeError: PyNaCl library needed in order to use voice

During handling of the above exception, another exception occurred:

Traceback (most recent call last):
  File "/home/pi/.local/lib/python3.7/site-packages/discord/client.py", line 312, in _run_event
    await coro(*args, **kwargs)
  File "aingbot.py", line 85, in on_message
    if not voice_client.is_playing():
AttributeError: 'NoneType' object has no attribute 'is_playing'
Ignoring exception in on_message
Traceback (most recent call last):
  File "/home/pi/.local/lib/python3.7/site-packages/discord/client.py", line 312, in _run_event
    await coro(*args, **kwargs)
  File "aingbot.py", line 75, in on_message
    channel = message.author.voice.channel
AttributeError: 'NoneType' object has no attribute 'channel'
Ignoring exception in on_message
Traceback (most recent call last):
  File "/home/pi/.local/lib/python3.7/site-packages/discord/client.py", line 312, in _run_event
    await coro(*args, **kwargs)
  File "aingbot.py", line 75, in on_message
    channel = message.author.voice.channel
AttributeError: 'NoneType' object has no attribute 'channel'
Ignoring exception in on_message
Traceback (most recent call last):
  File "/home/pi/.local/lib/python3.7/site-packages/discord/client.py", line 312, in _run_event
    await coro(*args, **kwargs)
  File "aingbot.py", line 75, in on_message
    channel = message.author.voice.channel
AttributeError: 'NoneType' object has no attribute 'channel'
Ignoring exception in on_message
Traceback (most recent call last):
  File "/home/pi/.local/lib/python3.7/site-packages/discord/client.py", line 312, in _run_event
    await coro(*args, **kwargs)
  File "aingbot.py", line 75, in on_message
    channel = message.author.voice.channel
AttributeError: 'NoneType' object has no attribute 'channel'
Ignoring exception in on_message
Traceback (most recent call last):
  File "aingbot.py", line 78, in on_message
    vc = await channel.connect()
  File "/home/pi/.local/lib/python3.7/site-packages/discord/abc.py", line 1097, in connect
    voice = VoiceClient(state=state, timeout=timeout, channel=self)
  File "/home/pi/.local/lib/python3.7/site-packages/discord/voice_client.py", line 90, in __init__
    raise RuntimeError("PyNaCl library needed in order to use voice")
RuntimeError: PyNaCl library needed in order to use voice

During handling of the above exception, another exception occurred:

Traceback (most recent call last):
  File "/home/pi/.local/lib/python3.7/site-packages/discord/client.py", line 312, in _run_event
    await coro(*args, **kwargs)
  File "aingbot.py", line 85, in on_message
    if not voice_client.is_playing():
AttributeError: 'NoneType' object has no attribute 'is_playing'
Ignoring exception in on_message
Traceback (most recent call last):
  File "aingbot.py", line 78, in on_message
    vc = await channel.connect()
  File "/home/pi/.local/lib/python3.7/site-packages/discord/abc.py", line 1097, in connect
    voice = VoiceClient(state=state, timeout=timeout, channel=self)
  File "/home/pi/.local/lib/python3.7/site-packages/discord/voice_client.py", line 90, in __init__
    raise RuntimeError("PyNaCl library needed in order to use voice")
RuntimeError: PyNaCl library needed in order to use voice

During handling of the above exception, another exception occurred:

Traceback (most recent call last):
  File "/home/pi/.local/lib/python3.7/site-packages/discord/client.py", line 312, in _run_event
    await coro(*args, **kwargs)
  File "aingbot.py", line 85, in on_message
    if not voice_client.is_playing():
AttributeError: 'NoneType' object has no attribute 'is_playing'
Ignoring exception in on_message
Traceback (most recent call last):
  File "aingbot.py", line 78, in on_message
    vc = await channel.connect()
  File "/home/pi/.local/lib/python3.7/site-packages/discord/abc.py", line 1097, in connect
    voice = VoiceClient(state=state, timeout=timeout, channel=self)
  File "/home/pi/.local/lib/python3.7/site-packages/discord/voice_client.py", line 90, in __init__
    raise RuntimeError("PyNaCl library needed in order to use voice")
RuntimeError: PyNaCl library needed in order to use voice

During handling of the above exception, another exception occurred:

Traceback (most recent call last):
  File "/home/pi/.local/lib/python3.7/site-packages/discord/client.py", line 312, in _run_event
    await coro(*args, **kwargs)
  File "aingbot.py", line 85, in on_message
    if not voice_client.is_playing():
AttributeError: 'NoneType' object has no attribute 'is_playing'
Ignoring exception in on_message
Traceback (most recent call last):
  File "/home/pi/.local/lib/python3.7/site-packages/discord/client.py", line 312, in _run_event
    await coro(*args, **kwargs)
  File "aingbot.py", line 75, in on_message
    channel = message.author.voice.channel
AttributeError: 'NoneType' object has no attribute 'channel'
Ignoring exception in on_message
Traceback (most recent call last):
  File "/home/pi/.local/lib/python3.7/site-packages/discord/client.py", line 312, in _run_event
    await coro(*args, **kwargs)
  File "aingbot.py", line 75, in on_message
    channel = message.author.voice.channel
AttributeError: 'NoneType' object has no attribute 'channel'
Ignoring exception in on_message
Traceback (most recent call last):
  File "/home/pi/.local/lib/python3.7/site-packages/discord/client.py", line 312, in _run_event
    await coro(*args, **kwargs)
  File "aingbot.py", line 75, in on_message
    channel = message.author.voice.channel
AttributeError: 'NoneType' object has no attribute 'channel'
Ignoring exception in on_message
Traceback (most recent call last):
  File "/home/pi/.local/lib/python3.7/site-packages/discord/client.py", line 312, in _run_event
    await coro(*args, **kwargs)
  File "aingbot.py", line 75, in on_message
    channel = message.author.voice.channel
AttributeError: 'NoneType' object has no attribute 'channel'
Ignoring exception in on_message
Traceback (most recent call last):
  File "/home/pi/.local/lib/python3.7/site-packages/discord/client.py", line 312, in _run_event
    await coro(*args, **kwargs)
  File "aingbot.py", line 75, in on_message
    channel = message.author.voice.channel
AttributeError: 'NoneType' object has no attribute 'channel'
Ignoring exception in on_message
Traceback (most recent call last):
  File "aingbot.py", line 78, in on_message
    vc = await channel.connect()
  File "/home/pi/.local/lib/python3.7/site-packages/discord/abc.py", line 1097, in connect
    voice = VoiceClient(state=state, timeout=timeout, channel=self)
  File "/home/pi/.local/lib/python3.7/site-packages/discord/voice_client.py", line 90, in __init__
    raise RuntimeError("PyNaCl library needed in order to use voice")
RuntimeError: PyNaCl library needed in order to use voice

During handling of the above exception, another exception occurred:

Traceback (most recent call last):
  File "/home/pi/.local/lib/python3.7/site-packages/discord/client.py", line 312, in _run_event
    await coro(*args, **kwargs)
  File "aingbot.py", line 85, in on_message
    if not voice_client.is_playing():
AttributeError: 'NoneType' object has no attribute 'is_playing'
Ignoring exception in on_message
Traceback (most recent call last):
  File "aingbot.py", line 78, in on_message
    vc = await channel.connect()
  File "/home/pi/.local/lib/python3.7/site-packages/discord/abc.py", line 1097, in connect
    voice = VoiceClient(state=state, timeout=timeout, channel=self)
  File "/home/pi/.local/lib/python3.7/site-packages/discord/voice_client.py", line 90, in __init__
    raise RuntimeError("PyNaCl library needed in order to use voice")
RuntimeError: PyNaCl library needed in order to use voice

During handling of the above exception, another exception occurred:

Traceback (most recent call last):
  File "/home/pi/.local/lib/python3.7/site-packages/discord/client.py", line 312, in _run_event
    await coro(*args, **kwargs)
  File "aingbot.py", line 85, in on_message
    if not voice_client.is_playing():
AttributeError: 'NoneType' object has no attribute 'is_playing'
Ignoring exception in on_message
Traceback (most recent call last):
  File "aingbot.py", line 78, in on_message
    vc = await channel.connect()
  File "/home/pi/.local/lib/python3.7/site-packages/discord/abc.py", line 1097, in connect
    voice = VoiceClient(state=state, timeout=timeout, channel=self)
  File "/home/pi/.local/lib/python3.7/site-packages/discord/voice_client.py", line 90, in __init__
    raise RuntimeError("PyNaCl library needed in order to use voice")
RuntimeError: PyNaCl library needed in order to use voice

During handling of the above exception, another exception occurred:

Traceback (most recent call last):
  File "/home/pi/.local/lib/python3.7/site-packages/discord/client.py", line 312, in _run_event
    await coro(*args, **kwargs)
  File "aingbot.py", line 85, in on_message
    if not voice_client.is_playing():
AttributeError: 'NoneType' object has no attribute 'is_playing'
Ignoring exception in on_message
Traceback (most recent call last):
  File "/home/pi/.local/lib/python3.7/site-packages/discord/client.py", line 312, in _run_event
    await coro(*args, **kwargs)
  File "aingbot.py", line 75, in on_message
    channel = message.author.voice.channel
AttributeError: 'NoneType' object has no attribute 'channel'
Ignoring exception in on_message
Traceback (most recent call last):
  File "/home/pi/.local/lib/python3.7/site-packages/discord/client.py", line 312, in _run_event
    await coro(*args, **kwargs)
  File "aingbot.py", line 75, in on_message
    channel = message.author.voice.channel
AttributeError: 'NoneType' object has no attribute 'channel'
Ignoring exception in on_message
Traceback (most recent call last):
  File "aingbot.py", line 78, in on_message
    vc = await channel.connect()
  File "/home/pi/.local/lib/python3.7/site-packages/discord/abc.py", line 1097, in connect
    voice = VoiceClient(state=state, timeout=timeout, channel=self)
  File "/home/pi/.local/lib/python3.7/site-packages/discord/voice_client.py", line 90, in __init__
    raise RuntimeError("PyNaCl library needed in order to use voice")
RuntimeError: PyNaCl library needed in order to use voice

During handling of the above exception, another exception occurred:

Traceback (most recent call last):
  File "/home/pi/.local/lib/python3.7/site-packages/discord/client.py", line 312, in _run_event
    await coro(*args, **kwargs)
  File "aingbot.py", line 85, in on_message
    if not voice_client.is_playing():
AttributeError: 'NoneType' object has no attribute 'is_playing'
Ignoring exception in on_message
Traceback (most recent call last):
  File "aingbot.py", line 78, in on_message
    vc = await channel.connect()
  File "/home/pi/.local/lib/python3.7/site-packages/discord/abc.py", line 1097, in connect
    voice = VoiceClient(state=state, timeout=timeout, channel=self)
  File "/home/pi/.local/lib/python3.7/site-packages/discord/voice_client.py", line 90, in __init__
    raise RuntimeError("PyNaCl library needed in order to use voice")
RuntimeError: PyNaCl library needed in order to use voice

During handling of the above exception, another exception occurred:

Traceback (most recent call last):
  File "/home/pi/.local/lib/python3.7/site-packages/discord/client.py", line 312, in _run_event
    await coro(*args, **kwargs)
  File "aingbot.py", line 85, in on_message
    if not voice_client.is_playing():
AttributeError: 'NoneType' object has no attribute 'is_playing'
Ignoring exception in on_message
Traceback (most recent call last):
  File "aingbot.py", line 78, in on_message
    vc = await channel.connect()
  File "/home/pi/.local/lib/python3.7/site-packages/discord/abc.py", line 1097, in connect
    voice = VoiceClient(state=state, timeout=timeout, channel=self)
  File "/home/pi/.local/lib/python3.7/site-packages/discord/voice_client.py", line 90, in __init__
    raise RuntimeError("PyNaCl library needed in order to use voice")
RuntimeError: PyNaCl library needed in order to use voice

During handling of the above exception, another exception occurred:

Traceback (most recent call last):
  File "/home/pi/.local/lib/python3.7/site-packages/discord/client.py", line 312, in _run_event
    await coro(*args, **kwargs)
  File "aingbot.py", line 85, in on_message
    if not voice_client.is_playing():
AttributeError: 'NoneType' object has no attribute 'is_playing'
Ignoring exception in on_message
Traceback (most recent call last):
  File "aingbot.py", line 78, in on_message
    vc = await channel.connect()
  File "/home/pi/.local/lib/python3.7/site-packages/discord/abc.py", line 1097, in connect
    voice = VoiceClient(state=state, timeout=timeout, channel=self)
  File "/home/pi/.local/lib/python3.7/site-packages/discord/voice_client.py", line 90, in __init__
    raise RuntimeError("PyNaCl library needed in order to use voice")
RuntimeError: PyNaCl library needed in order to use voice

During handling of the above exception, another exception occurred:

Traceback (most recent call last):
  File "/home/pi/.local/lib/python3.7/site-packages/discord/client.py", line 312, in _run_event
    await coro(*args, **kwargs)
  File "aingbot.py", line 85, in on_message
    if not voice_client.is_playing():
AttributeError: 'NoneType' object has no attribute 'is_playing'
Ignoring exception in on_message
Traceback (most recent call last):
  File "aingbot.py", line 78, in on_message
    vc = await channel.connect()
  File "/home/pi/.local/lib/python3.7/site-packages/discord/abc.py", line 1097, in connect
    voice = VoiceClient(state=state, timeout=timeout, channel=self)
  File "/home/pi/.local/lib/python3.7/site-packages/discord/voice_client.py", line 90, in __init__
    raise RuntimeError("PyNaCl library needed in order to use voice")
RuntimeError: PyNaCl library needed in order to use voice

During handling of the above exception, another exception occurred:

Traceback (most recent call last):
  File "/home/pi/.local/lib/python3.7/site-packages/discord/client.py", line 312, in _run_event
    await coro(*args, **kwargs)
  File "aingbot.py", line 85, in on_message
    if not voice_client.is_playing():
AttributeError: 'NoneType' object has no attribute 'is_playing'
Ignoring exception in on_message
Traceback (most recent call last):
  File "aingbot.py", line 78, in on_message
    vc = await channel.connect()
  File "/home/pi/.local/lib/python3.7/site-packages/discord/abc.py", line 1097, in connect
    voice = VoiceClient(state=state, timeout=timeout, channel=self)
  File "/home/pi/.local/lib/python3.7/site-packages/discord/voice_client.py", line 90, in __init__
    raise RuntimeError("PyNaCl library needed in order to use voice")
RuntimeError: PyNaCl library needed in order to use voice

During handling of the above exception, another exception occurred:

Traceback (most recent call last):
  File "/home/pi/.local/lib/python3.7/site-packages/discord/client.py", line 312, in _run_event
    await coro(*args, **kwargs)
  File "aingbot.py", line 85, in on_message
    if not voice_client.is_playing():
AttributeError: 'NoneType' object has no attribute 'is_playing'
Ignoring exception in on_message
Traceback (most recent call last):
  File "/home/pi/.local/lib/python3.7/site-packages/discord/client.py", line 312, in _run_event
    await coro(*args, **kwargs)
  File "aingbot.py", line 75, in on_message
    channel = message.author.voice.channel
AttributeError: 'NoneType' object has no attribute 'channel'
Ignoring exception in on_message
Traceback (most recent call last):
  File "/home/pi/.local/lib/python3.7/site-packages/discord/client.py", line 312, in _run_event
    await coro(*args, **kwargs)
  File "aingbot.py", line 75, in on_message
    channel = message.author.voice.channel
AttributeError: 'NoneType' object has no attribute 'channel'
websocket connection is closing.
Ignoring exception in on_message
Traceback (most recent call last):
  File "/home/pi/.local/lib/python3.7/site-packages/discord/client.py", line 312, in _run_event
    await coro(*args, **kwargs)
  File "dischat_2_w.py", line 217, in on_message
    await message.delete()
  File "/home/pi/.local/lib/python3.7/site-packages/discord/message.py", line 760, in delete
    await self._state.http.delete_message(self.channel.id, self.id)
  File "/home/pi/.local/lib/python3.7/site-packages/discord/http.py", line 243, in request
    raise NotFound(r, data)
discord.errors.NotFound: 404 Not Found (error code: 10008): Unknown Message
Ignoring exception in on_message
Traceback (most recent call last):
  File "/home/pi/.local/lib/python3.7/site-packages/discord/client.py", line 312, in _run_event
    await coro(*args, **kwargs)
  File "dischat_2_w.py", line 217, in on_message
    await message.delete()
  File "/home/pi/.local/lib/python3.7/site-packages/discord/message.py", line 760, in delete
    await self._state.http.delete_message(self.channel.id, self.id)
  File "/home/pi/.local/lib/python3.7/site-packages/discord/http.py", line 243, in request
    raise NotFound(r, data)
discord.errors.NotFound: 404 Not Found (error code: 10008): Unknown Message
Ignoring exception in on_message
Traceback (most recent call last):
  File "/home/pi/.local/lib/python3.7/site-packages/discord/client.py", line 312, in _run_event
    await coro(*args, **kwargs)
  File "dischat_2_w.py", line 217, in on_message
    await message.delete()
  File "/home/pi/.local/lib/python3.7/site-packages/discord/message.py", line 760, in delete
    await self._state.http.delete_message(self.channel.id, self.id)
  File "/home/pi/.local/lib/python3.7/site-packages/discord/http.py", line 243, in request
    raise NotFound(r, data)
discord.errors.NotFound: 404 Not Found (error code: 10008): Unknown Message
Ignoring exception in on_message
Traceback (most recent call last):
  File "/home/pi/.local/lib/python3.7/site-packages/discord/client.py", line 312, in _run_event
    await coro(*args, **kwargs)
  File "dischat_2_w.py", line 113, in on_message
    school_excel = maria_python.exe_sql(wday+1)
NameError: name 'wday' is not defined
Ignoring exception in on_message
Traceback (most recent call last):
  File "/home/pi/.local/lib/python3.7/site-packages/discord/client.py", line 312, in _run_event
    await coro(*args, **kwargs)
  File "dischat_2_w.py", line 113, in on_message
    school_excel = maria_python.exe_sql(wday+1)
NameError: name 'wday' is not defined
Ignoring exception in on_message
Traceback (most recent call last):
  File "/home/pi/.local/lib/python3.7/site-packages/discord/client.py", line 312, in _run_event
    await coro(*args, **kwargs)
  File "dischat_2_w.py", line 113, in on_message
    school_excel = maria_python.exe_sql(wday+1)
NameError: name 'wday' is not defined
Ignoring exception in on_message
Traceback (most recent call last):
  File "/home/pi/.local/lib/python3.7/site-packages/discord/client.py", line 312, in _run_event
    await coro(*args, **kwargs)
  File "dischat_2_w.py", line 113, in on_message
    school_excel = maria_python.exe_sql(wday+1)
NameError: name 'wday' is not defined
Ignoring exception in on_message
Traceback (most recent call last):
  File "/home/pi/.local/lib/python3.7/site-packages/discord/client.py", line 312, in _run_event
    await coro(*args, **kwargs)
  File "aingbot.py", line 75, in on_message
    channel = message.author.voice.channel
AttributeError: 'NoneType' object has no attribute 'channel'
websocket connection is closing.
websocket connection is closing.
websocket connection is closing.
Traceback (most recent call last):
  File "dischat_2_w.py", line 4, in <module>
    import discord
  File "/home/pi/.local/lib/python3.7/site-packages/discord/__init__.py", line 25, in <module>
    from .client import Client
  File "/home/pi/.local/lib/python3.7/site-packages/discord/client.py", line 34, in <module>
    import aiohttp
  File "/home/pi/.local/lib/python3.7/site-packages/aiohttp/__init__.py", line 6, in <module>
    from .client import BaseConnector as BaseConnector
  File "/home/pi/.local/lib/python3.7/site-packages/aiohttp/client.py", line 6, in <module>
    import json
  File "/usr/lib/python3.7/json/__init__.py", line 106, in <module>
    from .decoder import JSONDecoder, JSONDecodeError
  File "/usr/lib/python3.7/json/decoder.py", line 53, in <module>
    STRINGCHUNK = re.compile(r'(.*?)(["\\\x00-\x1f])', FLAGS)
  File "/usr/lib/python3.7/re.py", line 234, in compile
    return _compile(pattern, flags)
  File "/usr/lib/python3.7/re.py", line 286, in _compile
    p = sre_compile.compile(pattern, flags)
  File "/usr/lib/python3.7/sre_compile.py", line 764, in compile
    p = sre_parse.parse(p, flags)
  File "/usr/lib/python3.7/sre_parse.py", line 930, in parse
    p = _parse_sub(source, pattern, flags & SRE_FLAG_VERBOSE, 0)
  File "/usr/lib/python3.7/sre_parse.py", line 426, in _parse_sub
    not nested and not items))
  File "/usr/lib/python3.7/sre_parse.py", line 816, in _parse
    p = _parse_sub(source, state, sub_verbose, nested + 1)
  File "/usr/lib/python3.7/sre_parse.py", line 426, in _parse_sub
    not nested and not items))
  File "/usr/lib/python3.7/sre_parse.py", line 563, in _parse
    code2 = _class_escape(source, that)
  File "/usr/lib/python3.7/sre_parse.py", line 307, in _class_escape
    escape += source.getwhile(2, HEXDIGITS)
  File "/usr/lib/python3.7/sre_parse.py", line 265, in getwhile
    self.__next()
  File "/usr/lib/python3.7/sre_parse.py", line 234, in __next
    index = self.index
KeyboardInterrupt
websocket connection is closing.
SSL error in data received
protocol: <asyncio.sslproto.SSLProtocol object at 0x7484e650>
transport: <_SelectorSocketTransport fd=7 read=polling write=<idle, bufsize=0>>
Traceback (most recent call last):
  File "/usr/lib/python3.7/asyncio/sslproto.py", line 526, in data_received
    ssldata, appdata = self._sslpipe.feed_ssldata(data)
  File "/usr/lib/python3.7/asyncio/sslproto.py", line 207, in feed_ssldata
    self._sslobj.unwrap()
  File "/usr/lib/python3.7/ssl.py", line 767, in unwrap
    return self._sslobj.shutdown()
ssl.SSLError: [SSL: KRB5_S_INIT] application data after close notify (_ssl.c:2609)
websocket connection is closing.
websocket connection is closing.
websocket connection is closing.
websocket connection is closing.
websocket connection is closing.
Ignoring exception in on_message
Traceback (most recent call last):
  File "/home/pi/.local/lib/python3.7/site-packages/discord/client.py", line 312, in _run_event
    await coro(*args, **kwargs)
  File "dischat_2_w.py", line 217, in on_message
    await message.delete()
  File "/home/pi/.local/lib/python3.7/site-packages/discord/message.py", line 760, in delete
    await self._state.http.delete_message(self.channel.id, self.id)
  File "/home/pi/.local/lib/python3.7/site-packages/discord/http.py", line 243, in request
    raise NotFound(r, data)
discord.errors.NotFound: 404 Not Found (error code: 10008): Unknown Message
websocket connection is closing.
Ignoring exception in on_message
Traceback (most recent call last):
  File "/home/pi/.local/lib/python3.7/site-packages/discord/client.py", line 312, in _run_event
    await coro(*args, **kwargs)
  File "dischat_2_w.py", line 217, in on_message
    await message.delete()
  File "/home/pi/.local/lib/python3.7/site-packages/discord/message.py", line 760, in delete
    await self._state.http.delete_message(self.channel.id, self.id)
  File "/home/pi/.local/lib/python3.7/site-packages/discord/http.py", line 243, in request
    raise NotFound(r, data)
discord.errors.NotFound: 404 Not Found (error code: 10008): Unknown Message
Ignoring exception in on_message
Traceback (most recent call last):
  File "/home/pi/.local/lib/python3.7/site-packages/discord/client.py", line 312, in _run_event
    await coro(*args, **kwargs)
  File "dischat_2_w.py", line 217, in on_message
    await message.delete()
  File "/home/pi/.local/lib/python3.7/site-packages/discord/message.py", line 760, in delete
    await self._state.http.delete_message(self.channel.id, self.id)
  File "/home/pi/.local/lib/python3.7/site-packages/discord/http.py", line 243, in request
    raise NotFound(r, data)
discord.errors.NotFound: 404 Not Found (error code: 10008): Unknown Message
websocket connection is closing.
Ignoring exception in on_message
Traceback (most recent call last):
  File "/home/pi/.local/lib/python3.7/site-packages/discord/client.py", line 312, in _run_event
    await coro(*args, **kwargs)
  File "dischat_2_w.py", line 217, in on_message
    await message.delete()
  File "/home/pi/.local/lib/python3.7/site-packages/discord/message.py", line 760, in delete
    await self._state.http.delete_message(self.channel.id, self.id)
  File "/home/pi/.local/lib/python3.7/site-packages/discord/http.py", line 243, in request
    raise NotFound(r, data)
discord.errors.NotFound: 404 Not Found (error code: 10008): Unknown Message
Ignoring exception in on_message
Traceback (most recent call last):
  File "/home/pi/.local/lib/python3.7/site-packages/discord/client.py", line 312, in _run_event
    await coro(*args, **kwargs)
  File "dischat_2_w.py", line 217, in on_message
    await message.delete()
  File "/home/pi/.local/lib/python3.7/site-packages/discord/message.py", line 760, in delete
    await self._state.http.delete_message(self.channel.id, self.id)
  File "/home/pi/.local/lib/python3.7/site-packages/discord/http.py", line 243, in request
    raise NotFound(r, data)
discord.errors.NotFound: 404 Not Found (error code: 10008): Unknown Message
Ignoring exception in on_message
Traceback (most recent call last):
  File "/home/pi/.local/lib/python3.7/site-packages/discord/client.py", line 312, in _run_event
    await coro(*args, **kwargs)
  File "dischat_2_w.py", line 217, in on_message
    await message.delete()
  File "/home/pi/.local/lib/python3.7/site-packages/discord/message.py", line 760, in delete
    await self._state.http.delete_message(self.channel.id, self.id)
  File "/home/pi/.local/lib/python3.7/site-packages/discord/http.py", line 243, in request
    raise NotFound(r, data)
discord.errors.NotFound: 404 Not Found (error code: 10008): Unknown Message
Ignoring exception in on_message
Traceback (most recent call last):
  File "/home/pi/.local/lib/python3.7/site-packages/discord/client.py", line 312, in _run_event
    await coro(*args, **kwargs)
  File "dischat_2_w.py", line 217, in on_message
    await message.delete()
  File "/home/pi/.local/lib/python3.7/site-packages/discord/message.py", line 760, in delete
    await self._state.http.delete_message(self.channel.id, self.id)
  File "/home/pi/.local/lib/python3.7/site-packages/discord/http.py", line 243, in request
    raise NotFound(r, data)
discord.errors.NotFound: 404 Not Found (error code: 10008): Unknown Message
Ignoring exception in on_message
Traceback (most recent call last):
  File "/home/pi/.local/lib/python3.7/site-packages/discord/client.py", line 312, in _run_event
    await coro(*args, **kwargs)
  File "dischat_2_w.py", line 217, in on_message
    await message.delete()
  File "/home/pi/.local/lib/python3.7/site-packages/discord/message.py", line 760, in delete
    await self._state.http.delete_message(self.channel.id, self.id)
  File "/home/pi/.local/lib/python3.7/site-packages/discord/http.py", line 243, in request
    raise NotFound(r, data)
discord.errors.NotFound: 404 Not Found (error code: 10008): Unknown Message
Ignoring exception in on_message
Traceback (most recent call last):
  File "/home/pi/.local/lib/python3.7/site-packages/discord/client.py", line 312, in _run_event
    await coro(*args, **kwargs)
  File "dischat_2_w.py", line 217, in on_message
    await message.delete()
  File "/home/pi/.local/lib/python3.7/site-packages/discord/message.py", line 760, in delete
    await self._state.http.delete_message(self.channel.id, self.id)
  File "/home/pi/.local/lib/python3.7/site-packages/discord/http.py", line 243, in request
    raise NotFound(r, data)
discord.errors.NotFound: 404 Not Found (error code: 10008): Unknown Message
Ignoring exception in on_message
Traceback (most recent call last):
  File "/home/pi/.local/lib/python3.7/site-packages/discord/client.py", line 312, in _run_event
    await coro(*args, **kwargs)
  File "dischat_2_w.py", line 178, in on_message
    await message.delete()
  File "/home/pi/.local/lib/python3.7/site-packages/discord/message.py", line 760, in delete
    await self._state.http.delete_message(self.channel.id, self.id)
  File "/home/pi/.local/lib/python3.7/site-packages/discord/http.py", line 243, in request
    raise NotFound(r, data)
discord.errors.NotFound: 404 Not Found (error code: 10008): Unknown Message
Ignoring exception in on_message
Traceback (most recent call last):
  File "/home/pi/.local/lib/python3.7/site-packages/discord/client.py", line 312, in _run_event
    await coro(*args, **kwargs)
  File "dischat_2_w.py", line 178, in on_message
    await message.delete()
  File "/home/pi/.local/lib/python3.7/site-packages/discord/message.py", line 760, in delete
    await self._state.http.delete_message(self.channel.id, self.id)
  File "/home/pi/.local/lib/python3.7/site-packages/discord/http.py", line 243, in request
    raise NotFound(r, data)
discord.errors.NotFound: 404 Not Found (error code: 10008): Unknown Message
Ignoring exception in on_message
Traceback (most recent call last):
  File "/home/pi/.local/lib/python3.7/site-packages/discord/client.py", line 312, in _run_event
    await coro(*args, **kwargs)
  File "dischat_2_w.py", line 178, in on_message
    await message.delete()
  File "/home/pi/.local/lib/python3.7/site-packages/discord/message.py", line 760, in delete
    await self._state.http.delete_message(self.channel.id, self.id)
  File "/home/pi/.local/lib/python3.7/site-packages/discord/http.py", line 243, in request
    raise NotFound(r, data)
discord.errors.NotFound: 404 Not Found (error code: 10008): Unknown Message
Ignoring exception in on_message
Traceback (most recent call last):
  File "/home/pi/.local/lib/python3.7/site-packages/discord/client.py", line 312, in _run_event
    await coro(*args, **kwargs)
  File "dischat_2_w.py", line 217, in on_message
    await message.delete()
  File "/home/pi/.local/lib/python3.7/site-packages/discord/message.py", line 760, in delete
    await self._state.http.delete_message(self.channel.id, self.id)
  File "/home/pi/.local/lib/python3.7/site-packages/discord/http.py", line 243, in request
    raise NotFound(r, data)
discord.errors.NotFound: 404 Not Found (error code: 10008): Unknown Message
Ignoring exception in on_message
Traceback (most recent call last):
  File "/home/pi/.local/lib/python3.7/site-packages/discord/client.py", line 312, in _run_event
    await coro(*args, **kwargs)
  File "dischat_2_w.py", line 178, in on_message
    await message.delete()
  File "/home/pi/.local/lib/python3.7/site-packages/discord/message.py", line 760, in delete
    await self._state.http.delete_message(self.channel.id, self.id)
  File "/home/pi/.local/lib/python3.7/site-packages/discord/http.py", line 243, in request
    raise NotFound(r, data)
discord.errors.NotFound: 404 Not Found (error code: 10008): Unknown Message
Ignoring exception in on_message
Traceback (most recent call last):
  File "/home/pi/.local/lib/python3.7/site-packages/discord/client.py", line 312, in _run_event
    await coro(*args, **kwargs)
  File "dischat_2_w.py", line 178, in on_message
    await message.delete()
  File "/home/pi/.local/lib/python3.7/site-packages/discord/message.py", line 760, in delete
    await self._state.http.delete_message(self.channel.id, self.id)
  File "/home/pi/.local/lib/python3.7/site-packages/discord/http.py", line 243, in request
    raise NotFound(r, data)
discord.errors.NotFound: 404 Not Found (error code: 10008): Unknown Message
Ignoring exception in on_message
Traceback (most recent call last):
  File "/home/pi/.local/lib/python3.7/site-packages/discord/client.py", line 312, in _run_event
    await coro(*args, **kwargs)
  File "dischat_2_w.py", line 178, in on_message
    await message.delete()
  File "/home/pi/.local/lib/python3.7/site-packages/discord/message.py", line 760, in delete
    await self._state.http.delete_message(self.channel.id, self.id)
  File "/home/pi/.local/lib/python3.7/site-packages/discord/http.py", line 243, in request
    raise NotFound(r, data)
discord.errors.NotFound: 404 Not Found (error code: 10008): Unknown Message
Ignoring exception in on_message
Traceback (most recent call last):
  File "/home/pi/.local/lib/python3.7/site-packages/discord/client.py", line 312, in _run_event
    await coro(*args, **kwargs)
  File "dischat_2_w.py", line 178, in on_message
    await message.delete()
  File "/home/pi/.local/lib/python3.7/site-packages/discord/message.py", line 760, in delete
    await self._state.http.delete_message(self.channel.id, self.id)
  File "/home/pi/.local/lib/python3.7/site-packages/discord/http.py", line 243, in request
    raise NotFound(r, data)
discord.errors.NotFound: 404 Not Found (error code: 10008): Unknown Message
Ignoring exception in on_message
Traceback (most recent call last):
  File "/home/pi/.local/lib/python3.7/site-packages/discord/client.py", line 312, in _run_event
    await coro(*args, **kwargs)
  File "dischat_2_w.py", line 217, in on_message
    await message.delete()
  File "/home/pi/.local/lib/python3.7/site-packages/discord/message.py", line 760, in delete
    await self._state.http.delete_message(self.channel.id, self.id)
  File "/home/pi/.local/lib/python3.7/site-packages/discord/http.py", line 243, in request
    raise NotFound(r, data)
discord.errors.NotFound: 404 Not Found (error code: 10008): Unknown Message
Ignoring exception in on_message
Traceback (most recent call last):
  File "/home/pi/.local/lib/python3.7/site-packages/discord/client.py", line 312, in _run_event
    await coro(*args, **kwargs)
  File "dischat_2_w.py", line 178, in on_message
    await message.delete()
  File "/home/pi/.local/lib/python3.7/site-packages/discord/message.py", line 760, in delete
    await self._state.http.delete_message(self.channel.id, self.id)
  File "/home/pi/.local/lib/python3.7/site-packages/discord/http.py", line 243, in request
    raise NotFound(r, data)
discord.errors.NotFound: 404 Not Found (error code: 10008): Unknown Message
Ignoring exception in on_message
Traceback (most recent call last):
  File "/home/pi/.local/lib/python3.7/site-packages/discord/client.py", line 312, in _run_event
    await coro(*args, **kwargs)
  File "dischat_2_w.py", line 178, in on_message
    await message.delete()
  File "/home/pi/.local/lib/python3.7/site-packages/discord/message.py", line 760, in delete
    await self._state.http.delete_message(self.channel.id, self.id)
  File "/home/pi/.local/lib/python3.7/site-packages/discord/http.py", line 243, in request
    raise NotFound(r, data)
discord.errors.NotFound: 404 Not Found (error code: 10008): Unknown Message
Ignoring exception in on_message
Traceback (most recent call last):
  File "/home/pi/.local/lib/python3.7/site-packages/discord/client.py", line 312, in _run_event
    await coro(*args, **kwargs)
  File "dischat_2_w.py", line 178, in on_message
    await message.delete()
  File "/home/pi/.local/lib/python3.7/site-packages/discord/message.py", line 760, in delete
    await self._state.http.delete_message(self.channel.id, self.id)
  File "/home/pi/.local/lib/python3.7/site-packages/discord/http.py", line 243, in request
    raise NotFound(r, data)
discord.errors.NotFound: 404 Not Found (error code: 10008): Unknown Message
Ignoring exception in on_message
Traceback (most recent call last):
  File "/home/pi/.local/lib/python3.7/site-packages/discord/client.py", line 312, in _run_event
    await coro(*args, **kwargs)
  File "dischat_2_w.py", line 217, in on_message
    await message.delete()
  File "/home/pi/.local/lib/python3.7/site-packages/discord/message.py", line 760, in delete
    await self._state.http.delete_message(self.channel.id, self.id)
  File "/home/pi/.local/lib/python3.7/site-packages/discord/http.py", line 243, in request
    raise NotFound(r, data)
discord.errors.NotFound: 404 Not Found (error code: 10008): Unknown Message
Ignoring exception in on_message
Traceback (most recent call last):
  File "/home/pi/.local/lib/python3.7/site-packages/discord/client.py", line 312, in _run_event
    await coro(*args, **kwargs)
  File "dischat_2_w.py", line 178, in on_message
    await message.delete()
  File "/home/pi/.local/lib/python3.7/site-packages/discord/message.py", line 760, in delete
    await self._state.http.delete_message(self.channel.id, self.id)
  File "/home/pi/.local/lib/python3.7/site-packages/discord/http.py", line 243, in request
    raise NotFound(r, data)
discord.errors.NotFound: 404 Not Found (error code: 10008): Unknown Message
Ignoring exception in on_message
Traceback (most recent call last):
  File "/home/pi/.local/lib/python3.7/site-packages/discord/client.py", line 312, in _run_event
    await coro(*args, **kwargs)
  File "dischat_2_w.py", line 217, in on_message
    await message.delete()
  File "/home/pi/.local/lib/python3.7/site-packages/discord/message.py", line 760, in delete
    await self._state.http.delete_message(self.channel.id, self.id)
  File "/home/pi/.local/lib/python3.7/site-packages/discord/http.py", line 243, in request
    raise NotFound(r, data)
discord.errors.NotFound: 404 Not Found (error code: 10008): Unknown Message
Ignoring exception in on_message
Traceback (most recent call last):
  File "/home/pi/.local/lib/python3.7/site-packages/discord/client.py", line 312, in _run_event
    await coro(*args, **kwargs)
  File "dischat_2_w.py", line 178, in on_message
    await message.delete()
  File "/home/pi/.local/lib/python3.7/site-packages/discord/message.py", line 760, in delete
    await self._state.http.delete_message(self.channel.id, self.id)
  File "/home/pi/.local/lib/python3.7/site-packages/discord/http.py", line 243, in request
    raise NotFound(r, data)
discord.errors.NotFound: 404 Not Found (error code: 10008): Unknown Message
Ignoring exception in on_message
Traceback (most recent call last):
  File "/home/pi/.local/lib/python3.7/site-packages/discord/client.py", line 312, in _run_event
    await coro(*args, **kwargs)
  File "dischat_2_w.py", line 178, in on_message
    await message.delete()
  File "/home/pi/.local/lib/python3.7/site-packages/discord/message.py", line 760, in delete
    await self._state.http.delete_message(self.channel.id, self.id)
  File "/home/pi/.local/lib/python3.7/site-packages/discord/http.py", line 243, in request
    raise NotFound(r, data)
discord.errors.NotFound: 404 Not Found (error code: 10008): Unknown Message
Ignoring exception in on_message
Traceback (most recent call last):
  File "/home/pi/.local/lib/python3.7/site-packages/discord/client.py", line 312, in _run_event
    await coro(*args, **kwargs)
  File "dischat_2_w.py", line 178, in on_message
    await message.delete()
  File "/home/pi/.local/lib/python3.7/site-packages/discord/message.py", line 760, in delete
    await self._state.http.delete_message(self.channel.id, self.id)
  File "/home/pi/.local/lib/python3.7/site-packages/discord/http.py", line 243, in request
    raise NotFound(r, data)
discord.errors.NotFound: 404 Not Found (error code: 10008): Unknown Message
Ignoring exception in on_message
Traceback (most recent call last):
  File "/home/pi/.local/lib/python3.7/site-packages/discord/client.py", line 312, in _run_event
    await coro(*args, **kwargs)
  File "dischat_2_w.py", line 217, in on_message
    await message.delete()
  File "/home/pi/.local/lib/python3.7/site-packages/discord/message.py", line 760, in delete
    await self._state.http.delete_message(self.channel.id, self.id)
  File "/home/pi/.local/lib/python3.7/site-packages/discord/http.py", line 243, in request
    raise NotFound(r, data)
discord.errors.NotFound: 404 Not Found (error code: 10008): Unknown Message
Ignoring exception in on_message
Traceback (most recent call last):
  File "/home/pi/.local/lib/python3.7/site-packages/discord/client.py", line 312, in _run_event
    await coro(*args, **kwargs)
  File "dischat_2_w.py", line 217, in on_message
    await message.delete()
  File "/home/pi/.local/lib/python3.7/site-packages/discord/message.py", line 760, in delete
    await self._state.http.delete_message(self.channel.id, self.id)
  File "/home/pi/.local/lib/python3.7/site-packages/discord/http.py", line 243, in request
    raise NotFound(r, data)
discord.errors.NotFound: 404 Not Found (error code: 10008): Unknown Message
Ignoring exception in on_message
Traceback (most recent call last):
  File "/home/pi/.local/lib/python3.7/site-packages/discord/client.py", line 312, in _run_event
    await coro(*args, **kwargs)
  File "dischat_2_w.py", line 217, in on_message
    await message.delete()
  File "/home/pi/.local/lib/python3.7/site-packages/discord/message.py", line 760, in delete
    await self._state.http.delete_message(self.channel.id, self.id)
  File "/home/pi/.local/lib/python3.7/site-packages/discord/http.py", line 243, in request
    raise NotFound(r, data)
discord.errors.NotFound: 404 Not Found (error code: 10008): Unknown Message
Ignoring exception in on_message
Traceback (most recent call last):
  File "/home/pi/.local/lib/python3.7/site-packages/discord/client.py", line 312, in _run_event
    await coro(*args, **kwargs)
  File "dischat_2_w.py", line 217, in on_message
    await message.delete()
  File "/home/pi/.local/lib/python3.7/site-packages/discord/message.py", line 760, in delete
    await self._state.http.delete_message(self.channel.id, self.id)
  File "/home/pi/.local/lib/python3.7/site-packages/discord/http.py", line 243, in request
    raise NotFound(r, data)
discord.errors.NotFound: 404 Not Found (error code: 10008): Unknown Message
Ignoring exception in on_message
Traceback (most recent call last):
  File "/home/pi/.local/lib/python3.7/site-packages/discord/client.py", line 312, in _run_event
    await coro(*args, **kwargs)
  File "dischat_2_w.py", line 178, in on_message
    await message.delete()
  File "/home/pi/.local/lib/python3.7/site-packages/discord/message.py", line 760, in delete
    await self._state.http.delete_message(self.channel.id, self.id)
  File "/home/pi/.local/lib/python3.7/site-packages/discord/http.py", line 243, in request
    raise NotFound(r, data)
discord.errors.NotFound: 404 Not Found (error code: 10008): Unknown Message
Ignoring exception in on_message
Traceback (most recent call last):
  File "/home/pi/.local/lib/python3.7/site-packages/discord/client.py", line 312, in _run_event
    await coro(*args, **kwargs)
  File "dischat_2_w.py", line 217, in on_message
    await message.delete()
  File "/home/pi/.local/lib/python3.7/site-packages/discord/message.py", line 760, in delete
    await self._state.http.delete_message(self.channel.id, self.id)
  File "/home/pi/.local/lib/python3.7/site-packages/discord/http.py", line 243, in request
    raise NotFound(r, data)
discord.errors.NotFound: 404 Not Found (error code: 10008): Unknown Message
Ignoring exception in on_message
Traceback (most recent call last):
  File "/home/pi/.local/lib/python3.7/site-packages/discord/client.py", line 312, in _run_event
    await coro(*args, **kwargs)
  File "dischat_2_w.py", line 178, in on_message
    await message.delete()
  File "/home/pi/.local/lib/python3.7/site-packages/discord/message.py", line 760, in delete
    await self._state.http.delete_message(self.channel.id, self.id)
  File "/home/pi/.local/lib/python3.7/site-packages/discord/http.py", line 243, in request
    raise NotFound(r, data)
discord.errors.NotFound: 404 Not Found (error code: 10008): Unknown Message
Ignoring exception in on_message
Traceback (most recent call last):
  File "/home/pi/.local/lib/python3.7/site-packages/discord/client.py", line 312, in _run_event
    await coro(*args, **kwargs)
  File "dischat_2_w.py", line 178, in on_message
    await message.delete()
  File "/home/pi/.local/lib/python3.7/site-packages/discord/message.py", line 760, in delete
    await self._state.http.delete_message(self.channel.id, self.id)
  File "/home/pi/.local/lib/python3.7/site-packages/discord/http.py", line 243, in request
    raise NotFound(r, data)
discord.errors.NotFound: 404 Not Found (error code: 10008): Unknown Message
Ignoring exception in on_message
Traceback (most recent call last):
  File "/home/pi/.local/lib/python3.7/site-packages/discord/client.py", line 312, in _run_event
    await coro(*args, **kwargs)
  File "dischat_2_w.py", line 178, in on_message
    await message.delete()
  File "/home/pi/.local/lib/python3.7/site-packages/discord/message.py", line 760, in delete
    await self._state.http.delete_message(self.channel.id, self.id)
  File "/home/pi/.local/lib/python3.7/site-packages/discord/http.py", line 243, in request
    raise NotFound(r, data)
discord.errors.NotFound: 404 Not Found (error code: 10008): Unknown Message
Ignoring exception in on_message
Traceback (most recent call last):
  File "/home/pi/.local/lib/python3.7/site-packages/discord/client.py", line 312, in _run_event
    await coro(*args, **kwargs)
  File "dischat_2_w.py", line 178, in on_message
    await message.delete()
  File "/home/pi/.local/lib/python3.7/site-packages/discord/message.py", line 760, in delete
    await self._state.http.delete_message(self.channel.id, self.id)
  File "/home/pi/.local/lib/python3.7/site-packages/discord/http.py", line 243, in request
    raise NotFound(r, data)
discord.errors.NotFound: 404 Not Found (error code: 10008): Unknown Message
Ignoring exception in on_message
Traceback (most recent call last):
  File "/home/pi/.local/lib/python3.7/site-packages/discord/client.py", line 312, in _run_event
    await coro(*args, **kwargs)
  File "dischat_2_w.py", line 178, in on_message
    await message.delete()
  File "/home/pi/.local/lib/python3.7/site-packages/discord/message.py", line 760, in delete
    await self._state.http.delete_message(self.channel.id, self.id)
  File "/home/pi/.local/lib/python3.7/site-packages/discord/http.py", line 243, in request
    raise NotFound(r, data)
discord.errors.NotFound: 404 Not Found (error code: 10008): Unknown Message
Ignoring exception in on_message
Traceback (most recent call last):
  File "/home/pi/.local/lib/python3.7/site-packages/discord/client.py", line 312, in _run_event
    await coro(*args, **kwargs)
  File "dischat_2_w.py", line 178, in on_message
    await message.delete()
  File "/home/pi/.local/lib/python3.7/site-packages/discord/message.py", line 760, in delete
    await self._state.http.delete_message(self.channel.id, self.id)
  File "/home/pi/.local/lib/python3.7/site-packages/discord/http.py", line 243, in request
    raise NotFound(r, data)
discord.errors.NotFound: 404 Not Found (error code: 10008): Unknown Message
Ignoring exception in on_message
Traceback (most recent call last):
  File "/home/pi/.local/lib/python3.7/site-packages/discord/client.py", line 312, in _run_event
    await coro(*args, **kwargs)
  File "dischat_2_w.py", line 217, in on_message
    await message.delete()
  File "/home/pi/.local/lib/python3.7/site-packages/discord/message.py", line 760, in delete
    await self._state.http.delete_message(self.channel.id, self.id)
  File "/home/pi/.local/lib/python3.7/site-packages/discord/http.py", line 243, in request
    raise NotFound(r, data)
discord.errors.NotFound: 404 Not Found (error code: 10008): Unknown Message
Ignoring exception in on_message
Traceback (most recent call last):
  File "/home/pi/.local/lib/python3.7/site-packages/discord/client.py", line 312, in _run_event
    await coro(*args, **kwargs)
  File "dischat_2_w.py", line 217, in on_message
    await message.delete()
  File "/home/pi/.local/lib/python3.7/site-packages/discord/message.py", line 760, in delete
    await self._state.http.delete_message(self.channel.id, self.id)
  File "/home/pi/.local/lib/python3.7/site-packages/discord/http.py", line 243, in request
    raise NotFound(r, data)
discord.errors.NotFound: 404 Not Found (error code: 10008): Unknown Message
Ignoring exception in on_message
Traceback (most recent call last):
  File "/home/pi/.local/lib/python3.7/site-packages/discord/client.py", line 312, in _run_event
    await coro(*args, **kwargs)
  File "dischat_2_w.py", line 217, in on_message
    await message.delete()
  File "/home/pi/.local/lib/python3.7/site-packages/discord/message.py", line 760, in delete
    await self._state.http.delete_message(self.channel.id, self.id)
  File "/home/pi/.local/lib/python3.7/site-packages/discord/http.py", line 243, in request
    raise NotFound(r, data)
discord.errors.NotFound: 404 Not Found (error code: 10008): Unknown Message
Ignoring exception in on_message
Traceback (most recent call last):
  File "/home/pi/.local/lib/python3.7/site-packages/discord/client.py", line 312, in _run_event
    await coro(*args, **kwargs)
  File "dischat_2_w.py", line 217, in on_message
    await message.delete()
  File "/home/pi/.local/lib/python3.7/site-packages/discord/message.py", line 760, in delete
    await self._state.http.delete_message(self.channel.id, self.id)
  File "/home/pi/.local/lib/python3.7/site-packages/discord/http.py", line 243, in request
    raise NotFound(r, data)
discord.errors.NotFound: 404 Not Found (error code: 10008): Unknown Message
Ignoring exception in on_message
Traceback (most recent call last):
  File "/home/pi/.local/lib/python3.7/site-packages/discord/client.py", line 312, in _run_event
    await coro(*args, **kwargs)
  File "dischat_2_w.py", line 217, in on_message
    await message.delete()
  File "/home/pi/.local/lib/python3.7/site-packages/discord/message.py", line 760, in delete
    await self._state.http.delete_message(self.channel.id, self.id)
  File "/home/pi/.local/lib/python3.7/site-packages/discord/http.py", line 243, in request
    raise NotFound(r, data)
discord.errors.NotFound: 404 Not Found (error code: 10008): Unknown Message
Ignoring exception in on_message
Traceback (most recent call last):
  File "/home/pi/.local/lib/python3.7/site-packages/discord/client.py", line 312, in _run_event
    await coro(*args, **kwargs)
  File "dischat_2_w.py", line 217, in on_message
    await message.delete()
  File "/home/pi/.local/lib/python3.7/site-packages/discord/message.py", line 760, in delete
    await self._state.http.delete_message(self.channel.id, self.id)
  File "/home/pi/.local/lib/python3.7/site-packages/discord/http.py", line 243, in request
    raise NotFound(r, data)
discord.errors.NotFound: 404 Not Found (error code: 10008): Unknown Message
Ignoring exception in on_message
Traceback (most recent call last):
  File "/home/pi/.local/lib/python3.7/site-packages/discord/client.py", line 312, in _run_event
    await coro(*args, **kwargs)
  File "dischat_2_w.py", line 217, in on_message
    await message.delete()
  File "/home/pi/.local/lib/python3.7/site-packages/discord/message.py", line 760, in delete
    await self._state.http.delete_message(self.channel.id, self.id)
  File "/home/pi/.local/lib/python3.7/site-packages/discord/http.py", line 243, in request
    raise NotFound(r, data)
discord.errors.NotFound: 404 Not Found (error code: 10008): Unknown Message
Ignoring exception in on_message
Traceback (most recent call last):
  File "/home/pi/.local/lib/python3.7/site-packages/discord/client.py", line 312, in _run_event
    await coro(*args, **kwargs)
  File "dischat_2_w.py", line 217, in on_message
    await message.delete()
  File "/home/pi/.local/lib/python3.7/site-packages/discord/message.py", line 760, in delete
    await self._state.http.delete_message(self.channel.id, self.id)
  File "/home/pi/.local/lib/python3.7/site-packages/discord/http.py", line 243, in request
    raise NotFound(r, data)
discord.errors.NotFound: 404 Not Found (error code: 10008): Unknown Message
Ignoring exception in on_message
Traceback (most recent call last):
  File "/home/pi/.local/lib/python3.7/site-packages/discord/client.py", line 312, in _run_event
    await coro(*args, **kwargs)
  File "dischat_2_w.py", line 217, in on_message
    await message.delete()
  File "/home/pi/.local/lib/python3.7/site-packages/discord/message.py", line 760, in delete
    await self._state.http.delete_message(self.channel.id, self.id)
  File "/home/pi/.local/lib/python3.7/site-packages/discord/http.py", line 243, in request
    raise NotFound(r, data)
discord.errors.NotFound: 404 Not Found (error code: 10008): Unknown Message
Ignoring exception in on_message
Traceback (most recent call last):
  File "/home/pi/.local/lib/python3.7/site-packages/discord/client.py", line 312, in _run_event
    await coro(*args, **kwargs)
  File "dischat_2_w.py", line 217, in on_message
    await message.delete()
  File "/home/pi/.local/lib/python3.7/site-packages/discord/message.py", line 760, in delete
    await self._state.http.delete_message(self.channel.id, self.id)
  File "/home/pi/.local/lib/python3.7/site-packages/discord/http.py", line 243, in request
    raise NotFound(r, data)
discord.errors.NotFound: 404 Not Found (error code: 10008): Unknown Message
Ignoring exception in on_message
Traceback (most recent call last):
  File "/home/pi/.local/lib/python3.7/site-packages/discord/client.py", line 312, in _run_event
    await coro(*args, **kwargs)
  File "dischat_2_w.py", line 217, in on_message
    await message.delete()
  File "/home/pi/.local/lib/python3.7/site-packages/discord/message.py", line 760, in delete
    await self._state.http.delete_message(self.channel.id, self.id)
  File "/home/pi/.local/lib/python3.7/site-packages/discord/http.py", line 243, in request
    raise NotFound(r, data)
discord.errors.NotFound: 404 Not Found (error code: 10008): Unknown Message
Ignoring exception in on_message
Traceback (most recent call last):
  File "/home/pi/.local/lib/python3.7/site-packages/discord/client.py", line 312, in _run_event
    await coro(*args, **kwargs)
  File "dischat_2_w.py", line 217, in on_message
    await message.delete()
  File "/home/pi/.local/lib/python3.7/site-packages/discord/message.py", line 760, in delete
    await self._state.http.delete_message(self.channel.id, self.id)
  File "/home/pi/.local/lib/python3.7/site-packages/discord/http.py", line 243, in request
    raise NotFound(r, data)
discord.errors.NotFound: 404 Not Found (error code: 10008): Unknown Message
Ignoring exception in on_message
Traceback (most recent call last):
  File "/home/pi/.local/lib/python3.7/site-packages/discord/client.py", line 312, in _run_event
    await coro(*args, **kwargs)
  File "dischat_2_w.py", line 217, in on_message
    await message.delete()
  File "/home/pi/.local/lib/python3.7/site-packages/discord/message.py", line 760, in delete
    await self._state.http.delete_message(self.channel.id, self.id)
  File "/home/pi/.local/lib/python3.7/site-packages/discord/http.py", line 243, in request
    raise NotFound(r, data)
discord.errors.NotFound: 404 Not Found (error code: 10008): Unknown Message
Ignoring exception in on_message
Traceback (most recent call last):
  File "/home/pi/.local/lib/python3.7/site-packages/discord/client.py", line 312, in _run_event
    await coro(*args, **kwargs)
  File "dischat_2_w.py", line 217, in on_message
    await message.delete()
  File "/home/pi/.local/lib/python3.7/site-packages/discord/message.py", line 760, in delete
    await self._state.http.delete_message(self.channel.id, self.id)
  File "/home/pi/.local/lib/python3.7/site-packages/discord/http.py", line 243, in request
    raise NotFound(r, data)
discord.errors.NotFound: 404 Not Found (error code: 10008): Unknown Message
Ignoring exception in on_message
Traceback (most recent call last):
  File "/home/pi/.local/lib/python3.7/site-packages/discord/client.py", line 312, in _run_event
    await coro(*args, **kwargs)
  File "dischat_2_w.py", line 217, in on_message
    await message.delete()
  File "/home/pi/.local/lib/python3.7/site-packages/discord/message.py", line 760, in delete
    await self._state.http.delete_message(self.channel.id, self.id)
  File "/home/pi/.local/lib/python3.7/site-packages/discord/http.py", line 243, in request
    raise NotFound(r, data)
discord.errors.NotFound: 404 Not Found (error code: 10008): Unknown Message
Ignoring exception in on_message
Traceback (most recent call last):
  File "/home/pi/.local/lib/python3.7/site-packages/discord/client.py", line 312, in _run_event
    await coro(*args, **kwargs)
  File "dischat_2_w.py", line 217, in on_message
    await message.delete()
  File "/home/pi/.local/lib/python3.7/site-packages/discord/message.py", line 760, in delete
    await self._state.http.delete_message(self.channel.id, self.id)
  File "/home/pi/.local/lib/python3.7/site-packages/discord/http.py", line 243, in request
    raise NotFound(r, data)
discord.errors.NotFound: 404 Not Found (error code: 10008): Unknown Message
Ignoring exception in on_message
Traceback (most recent call last):
  File "/home/pi/.local/lib/python3.7/site-packages/discord/client.py", line 312, in _run_event
    await coro(*args, **kwargs)
  File "dischat_2_w.py", line 217, in on_message
    await message.delete()
Ignoring exception in on_message
Traceback (most recent call last):
  File "aingbot.py", line 78, in on_message
    vc = await channel.connect()
  File "/home/pi/.local/lib/python3.7/site-packages/discord/abc.py", line 1097, in connect
    voice = VoiceClient(state=state, timeout=timeout, channel=self)
  File "/home/pi/.local/lib/python3.7/site-packages/discord/voice_client.py", line 90, in __init__
    raise RuntimeError("PyNaCl library needed in order to use voice")
RuntimeError: PyNaCl library needed in order to use voice

During handling of the above exception, another exception occurred:

Traceback (most recent call last):
  File "/home/pi/.local/lib/python3.7/site-packages/discord/client.py", line 312, in _run_event
    await coro(*args, **kwargs)
  File "aingbot.py", line 85, in on_message
    if not voice_client.is_playing():
AttributeError: 'NoneType' object has no attribute 'is_playing'
Ignoring exception in on_message
Traceback (most recent call last):
  File "aingbot.py", line 78, in on_message
    vc = await channel.connect()
  File "/home/pi/.local/lib/python3.7/site-packages/discord/abc.py", line 1097, in connect
    voice = VoiceClient(state=state, timeout=timeout, channel=self)
  File "/home/pi/.local/lib/python3.7/site-packages/discord/voice_client.py", line 90, in __init__
    raise RuntimeError("PyNaCl library needed in order to use voice")
RuntimeError: PyNaCl library needed in order to use voice

During handling of the above exception, another exception occurred:

Traceback (most recent call last):
  File "/home/pi/.local/lib/python3.7/site-packages/discord/client.py", line 312, in _run_event
    await coro(*args, **kwargs)
  File "aingbot.py", line 85, in on_message
    if not voice_client.is_playing():
AttributeError: 'NoneType' object has no attribute 'is_playing'
Ignoring exception in on_message
Traceback (most recent call last):
  File "aingbot.py", line 78, in on_message
    vc = await channel.connect()
  File "/home/pi/.local/lib/python3.7/site-packages/discord/abc.py", line 1097, in connect
    voice = VoiceClient(state=state, timeout=timeout, channel=self)
  File "/home/pi/.local/lib/python3.7/site-packages/discord/voice_client.py", line 90, in __init__
    raise RuntimeError("PyNaCl library needed in order to use voice")
RuntimeError: PyNaCl library needed in order to use voice

During handling of the above exception, another exception occurred:

Traceback (most recent call last):
  File "/home/pi/.local/lib/python3.7/site-packages/discord/client.py", line 312, in _run_event
    await coro(*args, **kwargs)
  File "aingbot.py", line 85, in on_message
    if not voice_client.is_playing():
AttributeError: 'NoneType' object has no attribute 'is_playing'
Ignoring exception in on_message
Traceback (most recent call last):
  File "aingbot.py", line 78, in on_message
    vc = await channel.connect()
  File "/home/pi/.local/lib/python3.7/site-packages/discord/abc.py", line 1097, in connect
    voice = VoiceClient(state=state, timeout=timeout, channel=self)
  File "/home/pi/.local/lib/python3.7/site-packages/discord/voice_client.py", line 90, in __init__
    raise RuntimeError("PyNaCl library needed in order to use voice")
RuntimeError: PyNaCl library needed in order to use voice

During handling of the above exception, another exception occurred:

Traceback (most recent call last):
  File "/home/pi/.local/lib/python3.7/site-packages/discord/client.py", line 312, in _run_event
    await coro(*args, **kwargs)
  File "aingbot.py", line 85, in on_message
    if not voice_client.is_playing():
AttributeError: 'NoneType' object has no attribute 'is_playing'
Ignoring exception in on_message
Traceback (most recent call last):
  File "aingbot.py", line 78, in on_message
    vc = await channel.connect()
  File "/home/pi/.local/lib/python3.7/site-packages/discord/abc.py", line 1097, in connect
    voice = VoiceClient(state=state, timeout=timeout, channel=self)
  File "/home/pi/.local/lib/python3.7/site-packages/discord/voice_client.py", line 90, in __init__
    raise RuntimeError("PyNaCl library needed in order to use voice")
RuntimeError: PyNaCl library needed in order to use voice

During handling of the above exception, another exception occurred:

Traceback (most recent call last):
  File "/home/pi/.local/lib/python3.7/site-packages/discord/client.py", line 312, in _run_event
    await coro(*args, **kwargs)
  File "aingbot.py", line 85, in on_message
    if not voice_client.is_playing():
AttributeError: 'NoneType' object has no attribute 'is_playing'
Ignoring exception in on_message
Traceback (most recent call last):
  File "aingbot.py", line 78, in on_message
    vc = await channel.connect()
  File "/home/pi/.local/lib/python3.7/site-packages/discord/abc.py", line 1097, in connect
    voice = VoiceClient(state=state, timeout=timeout, channel=self)
  File "/home/pi/.local/lib/python3.7/site-packages/discord/voice_client.py", line 90, in __init__
    raise RuntimeError("PyNaCl library needed in order to use voice")
RuntimeError: PyNaCl library needed in order to use voice

During handling of the above exception, another exception occurred:

Traceback (most recent call last):
  File "/home/pi/.local/lib/python3.7/site-packages/discord/client.py", line 312, in _run_event
    await coro(*args, **kwargs)
  File "aingbot.py", line 85, in on_message
    if not voice_client.is_playing():
AttributeError: 'NoneType' object has no attribute 'is_playing'
Ignoring exception in on_message
Traceback (most recent call last):
  File "aingbot.py", line 78, in on_message
    vc = await channel.connect()
  File "/home/pi/.local/lib/python3.7/site-packages/discord/abc.py", line 1097, in connect
    voice = VoiceClient(state=state, timeout=timeout, channel=self)
  File "/home/pi/.local/lib/python3.7/site-packages/discord/voice_client.py", line 90, in __init__
    raise RuntimeError("PyNaCl library needed in order to use voice")
RuntimeError: PyNaCl library needed in order to use voice

During handling of the above exception, another exception occurred:

Traceback (most recent call last):
  File "/home/pi/.local/lib/python3.7/site-packages/discord/client.py", line 312, in _run_event
    await coro(*args, **kwargs)
  File "aingbot.py", line 85, in on_message
    if not voice_client.is_playing():
AttributeError: 'NoneType' object has no attribute 'is_playing'
Ignoring exception in on_message
Traceback (most recent call last):
  File "aingbot.py", line 78, in on_message
    vc = await channel.connect()
  File "/home/pi/.local/lib/python3.7/site-packages/discord/abc.py", line 1097, in connect
    voice = VoiceClient(state=state, timeout=timeout, channel=self)
  File "/home/pi/.local/lib/python3.7/site-packages/discord/voice_client.py", line 90, in __init__
    raise RuntimeError("PyNaCl library needed in order to use voice")
RuntimeError: PyNaCl library needed in order to use voice

During handling of the above exception, another exception occurred:

Traceback (most recent call last):
  File "/home/pi/.local/lib/python3.7/site-packages/discord/client.py", line 312, in _run_event
    await coro(*args, **kwargs)
  File "aingbot.py", line 85, in on_message
    if not voice_client.is_playing():
AttributeError: 'NoneType' object has no attribute 'is_playing'
websocket connection is closing.
websocket connection is closing.
  File "/home/pi/.local/lib/python3.7/site-packages/discord/message.py", line 760, in delete
    await self._state.http.delete_message(self.channel.id, self.id)
  File "/home/pi/.local/lib/python3.7/site-packages/discord/http.py", line 243, in request
    raise NotFound(r, data)
discord.errors.NotFound: 404 Not Found (error code: 10008): Unknown Message
Ignoring exception in on_message
Traceback (most recent call last):
  File "/home/pi/.local/lib/python3.7/site-packages/discord/client.py", line 312, in _run_event
    await coro(*args, **kwargs)
  File "dischat_2_w.py", line 217, in on_message
    await message.delete()
  File "/home/pi/.local/lib/python3.7/site-packages/discord/message.py", line 760, in delete
    await self._state.http.delete_message(self.channel.id, self.id)
  File "/home/pi/.local/lib/python3.7/site-packages/discord/http.py", line 243, in request
    raise NotFound(r, data)
discord.errors.NotFound: 404 Not Found (error code: 10008): Unknown Message
Ignoring exception in on_message
Traceback (most recent call last):
  File "/home/pi/.local/lib/python3.7/site-packages/discord/client.py", line 312, in _run_event
    await coro(*args, **kwargs)
  File "dischat_2_w.py", line 217, in on_message
    await message.delete()
  File "/home/pi/.local/lib/python3.7/site-packages/discord/message.py", line 760, in delete
    await self._state.http.delete_message(self.channel.id, self.id)
  File "/home/pi/.local/lib/python3.7/site-packages/discord/http.py", line 243, in request
    raise NotFound(r, data)
discord.errors.NotFound: 404 Not Found (error code: 10008): Unknown Message
Ignoring exception in on_message
Traceback (most recent call last):
  File "/home/pi/.local/lib/python3.7/site-packages/discord/client.py", line 312, in _run_event
    await coro(*args, **kwargs)
  File "dischat_2_w.py", line 217, in on_message
    await message.delete()
  File "/home/pi/.local/lib/python3.7/site-packages/discord/message.py", line 760, in delete
    await self._state.http.delete_message(self.channel.id, self.id)
  File "/home/pi/.local/lib/python3.7/site-packages/discord/http.py", line 243, in request
    raise NotFound(r, data)
discord.errors.NotFound: 404 Not Found (error code: 10008): Unknown Message
Ignoring exception in on_message
Traceback (most recent call last):
  File "/home/pi/.local/lib/python3.7/site-packages/discord/client.py", line 312, in _run_event
    await coro(*args, **kwargs)
  File "dischat_2_w.py", line 217, in on_message
    await message.delete()
  File "/home/pi/.local/lib/python3.7/site-packages/discord/message.py", line 760, in delete
    await self._state.http.delete_message(self.channel.id, self.id)
  File "/home/pi/.local/lib/python3.7/site-packages/discord/http.py", line 243, in request
    raise NotFound(r, data)
discord.errors.NotFound: 404 Not Found (error code: 10008): Unknown Message
Ignoring exception in on_message
Traceback (most recent call last):
  File "/home/pi/.local/lib/python3.7/site-packages/discord/client.py", line 312, in _run_event
    await coro(*args, **kwargs)
  File "dischat_2_w.py", line 217, in on_message
    await message.delete()
  File "/home/pi/.local/lib/python3.7/site-packages/discord/message.py", line 760, in delete
    await self._state.http.delete_message(self.channel.id, self.id)
  File "/home/pi/.local/lib/python3.7/site-packages/discord/http.py", line 243, in request
    raise NotFound(r, data)
discord.errors.NotFound: 404 Not Found (error code: 10008): Unknown Message
Ignoring exception in on_message
Traceback (most recent call last):
  File "/home/pi/.local/lib/python3.7/site-packages/discord/client.py", line 312, in _run_event
    await coro(*args, **kwargs)
  File "dischat_2_w.py", line 217, in on_message
    await message.delete()
  File "/home/pi/.local/lib/python3.7/site-packages/discord/message.py", line 760, in delete
    await self._state.http.delete_message(self.channel.id, self.id)
  File "/home/pi/.local/lib/python3.7/site-packages/discord/http.py", line 243, in request
    raise NotFound(r, data)
discord.errors.NotFound: 404 Not Found (error code: 10008): Unknown Message
Ignoring exception in on_message
Traceback (most recent call last):
  File "/home/pi/.local/lib/python3.7/site-packages/discord/client.py", line 312, in _run_event
    await coro(*args, **kwargs)
  File "dischat_2_w.py", line 217, in on_message
    await message.delete()
  File "/home/pi/.local/lib/python3.7/site-packages/discord/message.py", line 760, in delete
    await self._state.http.delete_message(self.channel.id, self.id)
  File "/home/pi/.local/lib/python3.7/site-packages/discord/http.py", line 243, in request
    raise NotFound(r, data)
discord.errors.NotFound: 404 Not Found (error code: 10008): Unknown Message
Ignoring exception in on_message
Traceback (most recent call last):
  File "/home/pi/.local/lib/python3.7/site-packages/discord/client.py", line 312, in _run_event
    await coro(*args, **kwargs)
  File "dischat_2_w.py", line 217, in on_message
    await message.delete()
  File "/home/pi/.local/lib/python3.7/site-packages/discord/message.py", line 760, in delete
    await self._state.http.delete_message(self.channel.id, self.id)
  File "/home/pi/.local/lib/python3.7/site-packages/discord/http.py", line 243, in request
    raise NotFound(r, data)
discord.errors.NotFound: 404 Not Found (error code: 10008): Unknown Message
Ignoring exception in on_message
Traceback (most recent call last):
  File "/home/pi/.local/lib/python3.7/site-packages/discord/client.py", line 312, in _run_event
    await coro(*args, **kwargs)
  File "dischat_2_w.py", line 217, in on_message
    await message.delete()
  File "/home/pi/.local/lib/python3.7/site-packages/discord/message.py", line 760, in delete
    await self._state.http.delete_message(self.channel.id, self.id)
  File "/home/pi/.local/lib/python3.7/site-packages/discord/http.py", line 243, in request
    raise NotFound(r, data)
discord.errors.NotFound: 404 Not Found (error code: 10008): Unknown Message
Ignoring exception in on_message
Traceback (most recent call last):
  File "/home/pi/.local/lib/python3.7/site-packages/discord/client.py", line 312, in _run_event
    await coro(*args, **kwargs)
  File "dischat_2_w.py", line 217, in on_message
    await message.delete()
  File "/home/pi/.local/lib/python3.7/site-packages/discord/message.py", line 760, in delete
    await self._state.http.delete_message(self.channel.id, self.id)
  File "/home/pi/.local/lib/python3.7/site-packages/discord/http.py", line 243, in request
    raise NotFound(r, data)
discord.errors.NotFound: 404 Not Found (error code: 10008): Unknown Message
Ignoring exception in on_message
Traceback (most recent call last):
  File "/home/pi/.local/lib/python3.7/site-packages/discord/client.py", line 312, in _run_event
    await coro(*args, **kwargs)
  File "dischat_2_w.py", line 217, in on_message
    await message.delete()
  File "/home/pi/.local/lib/python3.7/site-packages/discord/message.py", line 760, in delete
    await self._state.http.delete_message(self.channel.id, self.id)
  File "/home/pi/.local/lib/python3.7/site-packages/discord/http.py", line 243, in request
    raise NotFound(r, data)
discord.errors.NotFound: 404 Not Found (error code: 10008): Unknown Message
Ignoring exception in on_message
Traceback (most recent call last):
  File "/home/pi/.local/lib/python3.7/site-packages/discord/client.py", line 312, in _run_event
    await coro(*args, **kwargs)
  File "dischat_2_w.py", line 217, in on_message
    await message.delete()
  File "/home/pi/.local/lib/python3.7/site-packages/discord/message.py", line 760, in delete
    await self._state.http.delete_message(self.channel.id, self.id)
  File "/home/pi/.local/lib/python3.7/site-packages/discord/http.py", line 243, in request
    raise NotFound(r, data)
discord.errors.NotFound: 404 Not Found (error code: 10008): Unknown Message
Ignoring exception in on_message
Traceback (most recent call last):
  File "/home/pi/.local/lib/python3.7/site-packages/discord/client.py", line 312, in _run_event
    await coro(*args, **kwargs)
  File "dischat_2_w.py", line 217, in on_message
    await message.delete()
  File "/home/pi/.local/lib/python3.7/site-packages/discord/message.py", line 760, in delete
    await self._state.http.delete_message(self.channel.id, self.id)
  File "/home/pi/.local/lib/python3.7/site-packages/discord/http.py", line 243, in request
    raise NotFound(r, data)
discord.errors.NotFound: 404 Not Found (error code: 10008): Unknown Message
Ignoring exception in on_message
Traceback (most recent call last):
  File "/home/pi/.local/lib/python3.7/site-packages/discord/client.py", line 312, in _run_event
    await coro(*args, **kwargs)
  File "dischat_2_w.py", line 217, in on_message
    await message.delete()
  File "/home/pi/.local/lib/python3.7/site-packages/discord/message.py", line 760, in delete
    await self._state.http.delete_message(self.channel.id, self.id)
  File "/home/pi/.local/lib/python3.7/site-packages/discord/http.py", line 243, in request
    raise NotFound(r, data)
discord.errors.NotFound: 404 Not Found (error code: 10008): Unknown Message
Ignoring exception in on_message
Traceback (most recent call last):
  File "/home/pi/.local/lib/python3.7/site-packages/discord/client.py", line 312, in _run_event
    await coro(*args, **kwargs)
  File "dischat_2_w.py", line 217, in on_message
    await message.delete()
  File "/home/pi/.local/lib/python3.7/site-packages/discord/message.py", line 760, in delete
    await self._state.http.delete_message(self.channel.id, self.id)
  File "/home/pi/.local/lib/python3.7/site-packages/discord/http.py", line 243, in request
    raise NotFound(r, data)
discord.errors.NotFound: 404 Not Found (error code: 10008): Unknown Message
Ignoring exception in on_message
Traceback (most recent call last):
  File "/home/pi/.local/lib/python3.7/site-packages/discord/client.py", line 312, in _run_event
    await coro(*args, **kwargs)
  File "dischat_2_w.py", line 217, in on_message
    await message.delete()
  File "/home/pi/.local/lib/python3.7/site-packages/discord/message.py", line 760, in delete
    await self._state.http.delete_message(self.channel.id, self.id)
  File "/home/pi/.local/lib/python3.7/site-packages/discord/http.py", line 243, in request
    raise NotFound(r, data)
discord.errors.NotFound: 404 Not Found (error code: 10008): Unknown Message
Ignoring exception in on_message
Traceback (most recent call last):
  File "/home/pi/.local/lib/python3.7/site-packages/discord/client.py", line 312, in _run_event
    await coro(*args, **kwargs)
  File "dischat_2_w.py", line 217, in on_message
    await message.delete()
  File "/home/pi/.local/lib/python3.7/site-packages/discord/message.py", line 760, in delete
    await self._state.http.delete_message(self.channel.id, self.id)
  File "/home/pi/.local/lib/python3.7/site-packages/discord/http.py", line 243, in request
    raise NotFound(r, data)
discord.errors.NotFound: 404 Not Found (error code: 10008): Unknown Message
Ignoring exception in on_message
Traceback (most recent call last):
  File "/home/pi/.local/lib/python3.7/site-packages/discord/client.py", line 312, in _run_event
    await coro(*args, **kwargs)
  File "dischat_2_w.py", line 217, in on_message
    await message.delete()
  File "/home/pi/.local/lib/python3.7/site-packages/discord/message.py", line 760, in delete
    await self._state.http.delete_message(self.channel.id, self.id)
  File "/home/pi/.local/lib/python3.7/site-packages/discord/http.py", line 243, in request
    raise NotFound(r, data)
discord.errors.NotFound: 404 Not Found (error code: 10008): Unknown Message
Ignoring exception in on_message
Traceback (most recent call last):
  File "/home/pi/.local/lib/python3.7/site-packages/discord/client.py", line 312, in _run_event
    await coro(*args, **kwargs)
  File "dischat_2_w.py", line 217, in on_message
    await message.delete()
  File "/home/pi/.local/lib/python3.7/site-packages/discord/message.py", line 760, in delete
    await self._state.http.delete_message(self.channel.id, self.id)
  File "/home/pi/.local/lib/python3.7/site-packages/discord/http.py", line 243, in request
    raise NotFound(r, data)
discord.errors.NotFound: 404 Not Found (error code: 10008): Unknown Message
Ignoring exception in on_message
Traceback (most recent call last):
  File "/home/pi/.local/lib/python3.7/site-packages/discord/client.py", line 312, in _run_event
    await coro(*args, **kwargs)
  File "dischat_2_w.py", line 217, in on_message
    await message.delete()
  File "/home/pi/.local/lib/python3.7/site-packages/discord/message.py", line 760, in delete
    await self._state.http.delete_message(self.channel.id, self.id)
  File "/home/pi/.local/lib/python3.7/site-packages/discord/http.py", line 243, in request
    raise NotFound(r, data)
discord.errors.NotFound: 404 Not Found (error code: 10008): Unknown Message
Ignoring exception in on_message
Traceback (most recent call last):
  File "/home/pi/.local/lib/python3.7/site-packages/discord/client.py", line 312, in _run_event
    await coro(*args, **kwargs)
  File "dischat_2_w.py", line 217, in on_message
    await message.delete()
  File "/home/pi/.local/lib/python3.7/site-packages/discord/message.py", line 760, in delete
    await self._state.http.delete_message(self.channel.id, self.id)
  File "/home/pi/.local/lib/python3.7/site-packages/discord/http.py", line 243, in request
    raise NotFound(r, data)
discord.errors.NotFound: 404 Not Found (error code: 10008): Unknown Message
websocket connection is closing.
websocket connection is closing.
Ignoring exception in on_message
Traceback (most recent call last):
  File "/home/pi/.local/lib/python3.7/site-packages/discord/client.py", line 312, in _run_event
    await coro(*args, **kwargs)
  File "dischat_2_w.py", line 217, in on_message
    await message.delete()
  File "/home/pi/.local/lib/python3.7/site-packages/discord/message.py", line 760, in delete
    await self._state.http.delete_message(self.channel.id, self.id)
  File "/home/pi/.local/lib/python3.7/site-packages/discord/http.py", line 243, in request
    raise NotFound(r, data)
discord.errors.NotFound: 404 Not Found (error code: 10008): Unknown Message
Ignoring exception in on_message
Traceback (most recent call last):
  File "/home/pi/.local/lib/python3.7/site-packages/discord/client.py", line 312, in _run_event
    await coro(*args, **kwargs)
  File "dischat_2_w.py", line 217, in on_message
    await message.delete()
  File "/home/pi/.local/lib/python3.7/site-packages/discord/message.py", line 760, in delete
    await self._state.http.delete_message(self.channel.id, self.id)
  File "/home/pi/.local/lib/python3.7/site-packages/discord/http.py", line 243, in request
    raise NotFound(r, data)
discord.errors.NotFound: 404 Not Found (error code: 10008): Unknown Message
Ignoring exception in on_message
Traceback (most recent call last):
  File "/home/pi/.local/lib/python3.7/site-packages/discord/client.py", line 312, in _run_event
    await coro(*args, **kwargs)
  File "dischat_2_w.py", line 217, in on_message
    await message.delete()
  File "/home/pi/.local/lib/python3.7/site-packages/discord/message.py", line 760, in delete
    await self._state.http.delete_message(self.channel.id, self.id)
  File "/home/pi/.local/lib/python3.7/site-packages/discord/http.py", line 243, in request
    raise NotFound(r, data)
discord.errors.NotFound: 404 Not Found (error code: 10008): Unknown Message
Ignoring exception in on_message
Traceback (most recent call last):
  File "/home/pi/.local/lib/python3.7/site-packages/discord/client.py", line 312, in _run_event
    await coro(*args, **kwargs)
  File "dischat_2_w.py", line 217, in on_message
    await message.delete()
  File "/home/pi/.local/lib/python3.7/site-packages/discord/message.py", line 760, in delete
    await self._state.http.delete_message(self.channel.id, self.id)
  File "/home/pi/.local/lib/python3.7/site-packages/discord/http.py", line 243, in request
    raise NotFound(r, data)
discord.errors.NotFound: 404 Not Found (error code: 10008): Unknown Message
Ignoring exception in on_message
Traceback (most recent call last):
  File "/home/pi/.local/lib/python3.7/site-packages/discord/client.py", line 312, in _run_event
    await coro(*args, **kwargs)
  File "dischat_2_w.py", line 217, in on_message
    await message.delete()
  File "/home/pi/.local/lib/python3.7/site-packages/discord/message.py", line 760, in delete
    await self._state.http.delete_message(self.channel.id, self.id)
  File "/home/pi/.local/lib/python3.7/site-packages/discord/http.py", line 243, in request
    raise NotFound(r, data)
discord.errors.NotFound: 404 Not Found (error code: 10008): Unknown Message
Ignoring exception in on_message
Traceback (most recent call last):
  File "/home/pi/.local/lib/python3.7/site-packages/discord/client.py", line 312, in _run_event
    await coro(*args, **kwargs)
  File "dischat_2_w.py", line 217, in on_message
    await message.delete()
  File "/home/pi/.local/lib/python3.7/site-packages/discord/message.py", line 760, in delete
    await self._state.http.delete_message(self.channel.id, self.id)
  File "/home/pi/.local/lib/python3.7/site-packages/discord/http.py", line 243, in request
    raise NotFound(r, data)
discord.errors.NotFound: 404 Not Found (error code: 10008): Unknown Message
Ignoring exception in on_message
Traceback (most recent call last):
  File "/home/pi/.local/lib/python3.7/site-packages/discord/client.py", line 312, in _run_event
    await coro(*args, **kwargs)
  File "dischat_2_w.py", line 217, in on_message
    await message.delete()
  File "/home/pi/.local/lib/python3.7/site-packages/discord/message.py", line 760, in delete
    await self._state.http.delete_message(self.channel.id, self.id)
  File "/home/pi/.local/lib/python3.7/site-packages/discord/http.py", line 243, in request
    raise NotFound(r, data)
discord.errors.NotFound: 404 Not Found (error code: 10008): Unknown Message
Ignoring exception in on_message
Traceback (most recent call last):
  File "/home/pi/.local/lib/python3.7/site-packages/discord/client.py", line 312, in _run_event
    await coro(*args, **kwargs)
  File "dischat_2_w.py", line 217, in on_message
    await message.delete()
  File "/home/pi/.local/lib/python3.7/site-packages/discord/message.py", line 760, in delete
    await self._state.http.delete_message(self.channel.id, self.id)
  File "/home/pi/.local/lib/python3.7/site-packages/discord/http.py", line 243, in request
    raise NotFound(r, data)
discord.errors.NotFound: 404 Not Found (error code: 10008): Unknown Message
Ignoring exception in on_message
Traceback (most recent call last):
  File "/home/pi/.local/lib/python3.7/site-packages/discord/client.py", line 312, in _run_event
    await coro(*args, **kwargs)
  File "dischat_2_w.py", line 217, in on_message
    await message.delete()
  File "/home/pi/.local/lib/python3.7/site-packages/discord/message.py", line 760, in delete
    await self._state.http.delete_message(self.channel.id, self.id)
  File "/home/pi/.local/lib/python3.7/site-packages/discord/http.py", line 243, in request
    raise NotFound(r, data)
discord.errors.NotFound: 404 Not Found (error code: 10008): Unknown Message
Ignoring exception in on_message
Traceback (most recent call last):
  File "/home/pi/.local/lib/python3.7/site-packages/discord/client.py", line 312, in _run_event
    await coro(*args, **kwargs)
  File "dischat_2_w.py", line 217, in on_message
    await message.delete()
  File "/home/pi/.local/lib/python3.7/site-packages/discord/message.py", line 760, in delete
    await self._state.http.delete_message(self.channel.id, self.id)
  File "/home/pi/.local/lib/python3.7/site-packages/discord/http.py", line 243, in request
    raise NotFound(r, data)
discord.errors.NotFound: 404 Not Found (error code: 10008): Unknown Message
Ignoring exception in on_message
Traceback (most recent call last):
  File "/home/pi/.local/lib/python3.7/site-packages/discord/client.py", line 312, in _run_event
    await coro(*args, **kwargs)
  File "dischat_2_w.py", line 217, in on_message
    await message.delete()
  File "/home/pi/.local/lib/python3.7/site-packages/discord/message.py", line 760, in delete
    await self._state.http.delete_message(self.channel.id, self.id)
  File "/home/pi/.local/lib/python3.7/site-packages/discord/http.py", line 243, in request
    raise NotFound(r, data)
discord.errors.NotFound: 404 Not Found (error code: 10008): Unknown Message
Ignoring exception in on_message
Traceback (most recent call last):
  File "/home/pi/.local/lib/python3.7/site-packages/discord/client.py", line 312, in _run_event
    await coro(*args, **kwargs)
  File "dischat_2_w.py", line 217, in on_message
    await message.delete()
  File "/home/pi/.local/lib/python3.7/site-packages/discord/message.py", line 760, in delete
    await self._state.http.delete_message(self.channel.id, self.id)
  File "/home/pi/.local/lib/python3.7/site-packages/discord/http.py", line 243, in request
    raise NotFound(r, data)
discord.errors.NotFound: 404 Not Found (error code: 10008): Unknown Message
Ignoring exception in on_message
Traceback (most recent call last):
  File "/home/pi/.local/lib/python3.7/site-packages/discord/client.py", line 312, in _run_event
    await coro(*args, **kwargs)
  File "dischat_2_w.py", line 217, in on_message
    await message.delete()
  File "/home/pi/.local/lib/python3.7/site-packages/discord/message.py", line 760, in delete
    await self._state.http.delete_message(self.channel.id, self.id)
  File "/home/pi/.local/lib/python3.7/site-packages/discord/http.py", line 243, in request
    raise NotFound(r, data)
discord.errors.NotFound: 404 Not Found (error code: 10008): Unknown Message
Ignoring exception in on_message
Traceback (most recent call last):
  File "/home/pi/.local/lib/python3.7/site-packages/discord/client.py", line 312, in _run_event
    await coro(*args, **kwargs)
  File "dischat_2_w.py", line 217, in on_message
    await message.delete()
  File "/home/pi/.local/lib/python3.7/site-packages/discord/message.py", line 760, in delete
    await self._state.http.delete_message(self.channel.id, self.id)
  File "/home/pi/.local/lib/python3.7/site-packages/discord/http.py", line 243, in request
    raise NotFound(r, data)
discord.errors.NotFound: 404 Not Found (error code: 10008): Unknown Message
Ignoring exception in on_message
Traceback (most recent call last):
  File "/home/pi/.local/lib/python3.7/site-packages/discord/client.py", line 312, in _run_event
    await coro(*args, **kwargs)
  File "dischat_2_w.py", line 217, in on_message
    await message.delete()
  File "/home/pi/.local/lib/python3.7/site-packages/discord/message.py", line 760, in delete
    await self._state.http.delete_message(self.channel.id, self.id)
  File "/home/pi/.local/lib/python3.7/site-packages/discord/http.py", line 243, in request
    raise NotFound(r, data)
discord.errors.NotFound: 404 Not Found (error code: 10008): Unknown Message
Ignoring exception in on_message
Traceback (most recent call last):
  File "/home/pi/.local/lib/python3.7/site-packages/discord/client.py", line 312, in _run_event
    await coro(*args, **kwargs)
  File "dischat_2_w.py", line 217, in on_message
    await message.delete()
  File "/home/pi/.local/lib/python3.7/site-packages/discord/message.py", line 760, in delete
    await self._state.http.delete_message(self.channel.id, self.id)
  File "/home/pi/.local/lib/python3.7/site-packages/discord/http.py", line 243, in request
    raise NotFound(r, data)
discord.errors.NotFound: 404 Not Found (error code: 10008): Unknown Message
websocket connection is closing.
websocket connection is closing.
Ignoring exception in on_message
Traceback (most recent call last):
  File "/home/pi/.local/lib/python3.7/site-packages/discord/client.py", line 312, in _run_event
    await coro(*args, **kwargs)
  File "aingbot.py", line 75, in on_message
    channel = message.author.voice.channel
AttributeError: 'NoneType' object has no attribute 'channel'
Ignoring exception in on_message
Traceback (most recent call last):
  File "/home/pi/.local/lib/python3.7/site-packages/discord/client.py", line 312, in _run_event
    await coro(*args, **kwargs)
  File "aingbot.py", line 75, in on_message
    channel = message.author.voice.channel
AttributeError: 'NoneType' object has no attribute 'channel'
Ignoring exception in on_message
Traceback (most recent call last):
  File "/home/pi/.local/lib/python3.7/site-packages/discord/client.py", line 312, in _run_event
    await coro(*args, **kwargs)
  File "aingbot.py", line 75, in on_message
    channel = message.author.voice.channel
AttributeError: 'NoneType' object has no attribute 'channel'
websocket connection is closing.
